Workbook
Name BUENAVISTA: nombres!$D$105:$D$109
Name GIVAUDAN: nombres!$D$100:$D$102
Name HUIMILPAN: nombres!$D$58:$D$99
Name LIRA_GALERAS: nombres!$D$2:$D$41
Name PECO_AGROS: nombres!$D$42:$D$57
Name PIE_DE_GALLO: nombres!$D$110:$D$121
Name SAN_GIL: nombres!$D$103:$D$104
Name SegmentaciónDeDatos_nombre_actividad: #N/A

Sheet diario
A1: Fecha | B1: Brigada | C1: Sistema | D1: Ducto | E1: Actividades | F1: inicio | G1: fin | H1: Avance_km | I1: Avance_Med | J1: Codigo_actividad | K1: nombre_actividad | L1: Length | M1: EV | N1: Observaciones
A2: 45964 | B2: A | C2: LIRA_GALERAS | D2: AC 8-6-4 in La Lira-Galeras | E2: Reunión de arranque y revisión de información oficinas ENGIE Querétaro. Localización de Tubería con Equipo de RadioDetección. | F2: 0 | G2: 1100 | H2: =IF(Tabla1[[#This Row],[Codigo_actividad]]<>2.5,IF(((Tabla1[[#This Row],[fin]]-Tabla1[[#This Row],[inicio]])/1000)=0,"",((Tabla1[[#This Row],[fin]]-Tabla1[[#This Row],[inicio]])/1000)),"") -> 1.1 | J2: 2.6 | K2: =IF(_xlfn.XLOOKUP($J2,Catalogo!$B$7:$B$210,Catalogo!$I$7:$I$210,"",0)=0,"",_xlfn.XLOOKUP($J2,Catalogo!$B$7:$B$210,Catalogo!$I$7:$I$210,"",0)) -> Localizacion | L2: 31.54 | M2: =IF(Tabla1[[#This Row],[Avance_km]]<>"",Tabla1[[#This Row],[Avance_km]],Tabla1[[#This Row],[Avance_Med]])*_xlfn.XLOOKUP(Tabla1[[#This Row],[Codigo_actividad]],Catalogo!$B$6:$B$51,Catalogo!$F$6:$F$51,0) -> 2483.162
A3: 45965 | B3: A | C3: LIRA_GALERAS | D3: AC 8-6-4 in La Lira-Galeras | E3: Localización de Tubería con Equipo de RadioDetección. | F3: 1100 | G3: 4000 | H3: =IF(Tabla1[[#This Row],[Codigo_actividad]]<>2.5,IF(((Tabla1[[#This Row],[fin]]-Tabla1[[#This Row],[inicio]])/1000)=0,"",((Tabla1[[#This Row],[fin]]-Tabla1[[#This Row],[inicio]])/1000)),"") -> 2.9 | J3: 2.6 | K3: =IF(_xlfn.XLOOKUP($J3,Catalogo!$B$7:$B$210,Catalogo!$I$7:$I$210,"",0)=0,"",_xlfn.XLOOKUP($J3,Catalogo!$B$7:$B$210,Catalogo!$I$7:$I$210,"",0)) -> Localizacion | L3: 31.54 | M3: =IF(Tabla1[[#This Row],[Avance_km]]<>"",Tabla1[[#This Row],[Avance_km]],Tabla1[[#This Row],[Avance_Med]])*_xlfn.XLOOKUP(Tabla1[[#This Row],[Codigo_actividad]],Catalogo!$B$6:$B$51,Catalogo!$F$6:$F$51,0) -> 6546.518
A4: 45966 | B4: A | C4: LIRA_GALERAS | D4: AC 8-6-4 in La Lira-Galeras | E4: Localización de Tubería con Equipo de RadioDetección. | F4: 4000 | G4: 8000 | H4: =IF(Tabla1[[#This Row],[Codigo_actividad]]<>2.5,IF(((Tabla1[[#This Row],[fin]]-Tabla1[[#This Row],[inicio]])/1000)=0,"",((Tabla1[[#This Row],[fin]]-Tabla1[[#This Row],[inicio]])/1000)),"") -> 4 | J4: 2.6 | K4: =IF(_xlfn.XLOOKUP($J4,Catalogo!$B$7:$B$210,Catalogo!$I$7:$I$210,"",0)=0,"",_xlfn.XLOOKUP($J4,Catalogo!$B$7:$B$210,Catalogo!$I$7:$I$210,"",0)) -> Localizacion | L4: 31.54 | M4: =IF(Tabla1[[#This Row],[Avance_km]]<>"",Tabla1[[#This Row],[Avance_km]],Tabla1[[#This Row],[Avance_Med]])*_xlfn.XLOOKUP(Tabla1[[#This Row],[Codigo_actividad]],Catalogo!$B$6:$B$51,Catalogo!$F$6:$F$51,0) -> 9029.68
A5: 45967 | B5: A | C5: LIRA_GALERAS | D5: AC 8-6-4 in La Lira-Galeras | E5: Localización de Tubería con Equipo de RadioDetección. | F5: 8000 | G5: 13500 | H5: =IF(Tabla1[[#This Row],[Codigo_actividad]]<>2.5,IF(((Tabla1[[#This Row],[fin]]-Tabla1[[#This Row],[inicio]])/1000)=0,"",((Tabla1[[#This Row],[fin]]-Tabla1[[#This Row],[inicio]])/1000)),"") -> 5.5 | J5: 2.6 | K5: =IF(_xlfn.XLOOKUP($J5,Catalogo!$B$7:$B$210,Catalogo!$I$7:$I$210,"",0)=0,"",_xlfn.XLOOKUP($J5,Catalogo!$B$7:$B$210,Catalogo!$I$7:$I$210,"",0)) -> Localizacion | L5: 31.54 | M5: =IF(Tabla1[[#This Row],[Avance_km]]<>"",Tabla1[[#This Row],[Avance_km]],Tabla1[[#This Row],[Avance_Med]])*_xlfn.XLOOKUP(Tabla1[[#This Row],[Codigo_actividad]],Catalogo!$B$6:$B$51,Catalogo!$F$6:$F$51,0) -> 12415.81
A6: 45968 | B6: A | C6: LIRA_GALERAS | D6: AC 8-6-4 in La Lira-Galeras | E6: Localización de Tubería con Equipo de RadioDetección. | F6: 13500 | G6: 17500 | H6: =IF(Tabla1[[#This Row],[Codigo_actividad]]<>2.5,IF(((Tabla1[[#This Row],[fin]]-Tabla1[[#This Row],[inicio]])/1000)=0,"",((Tabla1[[#This Row],[fin]]-Tabla1[[#This Row],[inicio]])/1000)),"") -> 4 | J6: 2.6 | K6: =IF(_xlfn.XLOOKUP($J6,Catalogo!$B$7:$B$210,Catalogo!$I$7:$I$210,"",0)=0,"",_xlfn.XLOOKUP($J6,Catalogo!$B$7:$B$210,Catalogo!$I$7:$I$210,"",0)) -> Localizacion | L6: 31.54 | M6: =IF(Tabla1[[#This Row],[Avance_km]]<>"",Tabla1[[#This Row],[Avance_km]],Tabla1[[#This Row],[Avance_Med]])*_xlfn.XLOOKUP(Tabla1[[#This Row],[Codigo_actividad]],Catalogo!$B$6:$B$51,Catalogo!$F$6:$F$51,0) -> 9029.68
A7: 45969 | B7: A | C7: LIRA_GALERAS | D7: AC 8-6-4 in La Lira-Galeras | E7: Localización de Tubería con Equipo de RadioDetección. | F7: 17500 | G7: 20500 | H7: =IF(Tabla1[[#This Row],[Codigo_actividad]]<>2.5,IF(((Tabla1[[#This Row],[fin]]-Tabla1[[#This Row],[inicio]])/1000)=0,"",((Tabla1[[#This Row],[fin]]-Tabla1[[#This Row],[inicio]])/1000)),"") -> 3 | J7: 2.6 | K7: =IF(_xlfn.XLOOKUP($J7,Catalogo!$B$7:$B$210,Catalogo!$I$7:$I$210,"",0)=0,"",_xlfn.XLOOKUP($J7,Catalogo!$B$7:$B$210,Catalogo!$I$7:$I$210,"",0)) -> Localizacion | L7: 31.54 | M7: =IF(Tabla1[[#This Row],[Avance_km]]<>"",Tabla1[[#This Row],[Avance_km]],Tabla1[[#This Row],[Avance_Med]])*_xlfn.XLOOKUP(Tabla1[[#This Row],[Codigo_actividad]],Catalogo!$B$6:$B$51,Catalogo!$F$6:$F$51,0) -> 6772.26
A8: 45971 | B8: A | C8: LIRA_GALERAS | D8: AC 8-6-4 in La Lira-Galeras | E8: Localización de Tubería con Equipo de RadioDetección. | F8: 20500 | G8: 26000 | H8: =IF(Tabla1[[#This Row],[Codigo_actividad]]<>2.5,IF(((Tabla1[[#This Row],[fin]]-Tabla1[[#This Row],[inicio]])/1000)=0,"",((Tabla1[[#This Row],[fin]]-Tabla1[[#This Row],[inicio]])/1000)),"") -> 5.5 | J8: 2.6 | K8: =IF(_xlfn.XLOOKUP($J8,Catalogo!$B$7:$B$210,Catalogo!$I$7:$I$210,"",0)=0,"",_xlfn.XLOOKUP($J8,Catalogo!$B$7:$B$210,Catalogo!$I$7:$I$210,"",0)) -> Localizacion | L8: 31.54 | M8: =IF(Tabla1[[#This Row],[Avance_km]]<>"",Tabla1[[#This Row],[Avance_km]],Tabla1[[#This Row],[Avance_Med]])*_xlfn.XLOOKUP(Tabla1[[#This Row],[Codigo_actividad]],Catalogo!$B$6:$B$51,Catalogo!$F$6:$F$51,0) -> 12415.81
A9: 45972 | B9: A | C9: LIRA_GALERAS | D9: AC 8-6-4 in La Lira-Galeras | E9: Localización de Tubería con Equipo de RadioDetección. | F9: 26000 | G9: 31540 | H9: =IF(Tabla1[[#This Row],[Codigo_actividad]]<>2.5,IF(((Tabla1[[#This Row],[fin]]-Tabla1[[#This Row],[inicio]])/1000)=0,"",((Tabla1[[#This Row],[fin]]-Tabla1[[#This Row],[inicio]])/1000)),"") -> 5.54 | J9: 2.6 | K9: =IF(_xlfn.XLOOKUP($J9,Catalogo!$B$7:$B$210,Catalogo!$I$7:$I$210,"",0)=0,"",_xlfn.XLOOKUP($J9,Catalogo!$B$7:$B$210,Catalogo!$I$7:$I$210,"",0)) -> Localizacion | L9: 31.54 | M9: =IF(Tabla1[[#This Row],[Avance_km]]<>"",Tabla1[[#This Row],[Avance_km]],Tabla1[[#This Row],[Avance_Med]])*_xlfn.XLOOKUP(Tabla1[[#This Row],[Codigo_actividad]],Catalogo!$B$6:$B$51,Catalogo!$F$6:$F$51,0) -> 12506.107
A10: 45973 | B10: A | C10: LIRA_GALERAS | D10: ALESTRA | E10: Localización de Tubería con Equipo de RadioDetección. | F10: 0 | G10: 1982 | H10: =IF(Tabla1[[#This Row],[Codigo_actividad]]<>2.5,IF(((Tabla1[[#This Row],[fin]]-Tabla1[[#This Row],[inicio]])/1000)=0,"",((Tabla1[[#This Row],[fin]]-Tabla1[[#This Row],[inicio]])/1000)),"") -> 1.982 | J10: 2.6 | K10: =IF(_xlfn.XLOOKUP($J10,Catalogo!$B$7:$B$210,Catalogo!$I$7:$I$210,"",0)=0,"",_xlfn.XLOOKUP($J10,Catalogo!$B$7:$B$210,Catalogo!$I$7:$I$210,"",0)) -> Localizacion | L10: 1.982 | M10: =IF(Tabla1[[#This Row],[Avance_km]]<>"",Tabla1[[#This Row],[Avance_km]],Tabla1[[#This Row],[Avance_Med]])*_xlfn.XLOOKUP(Tabla1[[#This Row],[Codigo_actividad]],Catalogo!$B$6:$B$51,Catalogo!$F$6:$F$51,0) -> 4474.2064
A11: 45973 | B11: A | C11: LIRA_GALERAS | D11: HUAWEI | E11: Localización de Tubería con Equipo de RadioDetección. | F11: 0 | G11: 175 | H11: =IF(Tabla1[[#This Row],[Codigo_actividad]]<>2.5,IF(((Tabla1[[#This Row],[fin]]-Tabla1[[#This Row],[inicio]])/1000)=0,"",((Tabla1[[#This Row],[fin]]-Tabla1[[#This Row],[inicio]])/1000)),"") -> 0.175 | J11: 2.6 | K11: =IF(_xlfn.XLOOKUP($J11,Catalogo!$B$7:$B$210,Catalogo!$I$7:$I$210,"",0)=0,"",_xlfn.XLOOKUP($J11,Catalogo!$B$7:$B$210,Catalogo!$I$7:$I$210,"",0)) -> Localizacion | L11: 0.175 | M11: =IF(Tabla1[[#This Row],[Avance_km]]<>"",Tabla1[[#This Row],[Avance_km]],Tabla1[[#This Row],[Avance_Med]])*_xlfn.XLOOKUP(Tabla1[[#This Row],[Codigo_actividad]],Catalogo!$B$6:$B$51,Catalogo!$F$6:$F$51,0) -> 395.0485
A12: 45973 | B12: A | C12: LIRA_GALERAS | D12: ITASA | E12: Localización de Tubería con Equipo de RadioDetección. | F12: 0 | G12: 15 | H12: =IF(Tabla1[[#This Row],[Codigo_actividad]]<>2.5,IF(((Tabla1[[#This Row],[fin]]-Tabla1[[#This Row],[inicio]])/1000)=0,"",((Tabla1[[#This Row],[fin]]-Tabla1[[#This Row],[inicio]])/1000)),"") -> 0.015 | J12: 2.6 | K12: =IF(_xlfn.XLOOKUP($J12,Catalogo!$B$7:$B$210,Catalogo!$I$7:$I$210,"",0)=0,"",_xlfn.XLOOKUP($J12,Catalogo!$B$7:$B$210,Catalogo!$I$7:$I$210,"",0)) -> Localizacion | L12: 0.015 | M12: =IF(Tabla1[[#This Row],[Avance_km]]<>"",Tabla1[[#This Row],[Avance_km]],Tabla1[[#This Row],[Avance_Med]])*_xlfn.XLOOKUP(Tabla1[[#This Row],[Codigo_actividad]],Catalogo!$B$6:$B$51,Catalogo!$F$6:$F$51,0) -> 33.8613
A13: 45973 | B13: A | C13: LIRA_GALERAS | D13: ED PARQUE INDUSTRIAL FINSA II | E13: Localización de Tubería con Equipo de RadioDetección. | F13: 0 | G13: 1020 | H13: =IF(Tabla1[[#This Row],[Codigo_actividad]]<>2.5,IF(((Tabla1[[#This Row],[fin]]-Tabla1[[#This Row],[inicio]])/1000)=0,"",((Tabla1[[#This Row],[fin]]-Tabla1[[#This Row],[inicio]])/1000)),"") -> 1.02 | J13: 2.6 | K13: =IF(_xlfn.XLOOKUP($J13,Catalogo!$B$7:$B$210,Catalogo!$I$7:$I$210,"",0)=0,"",_xlfn.XLOOKUP($J13,Catalogo!$B$7:$B$210,Catalogo!$I$7:$I$210,"",0)) -> Localizacion | L13: 1.02 | M13: =IF(Tabla1[[#This Row],[Avance_km]]<>"",Tabla1[[#This Row],[Avance_km]],Tabla1[[#This Row],[Avance_Med]])*_xlfn.XLOOKUP(Tabla1[[#This Row],[Codigo_actividad]],Catalogo!$B$6:$B$51,Catalogo!$F$6:$F$51,0) -> 2302.5684
... A25: 45980 | B25: B | C25: PECO_AGROS | D25: PECO II - GALERAS 10 | E25: Localización de Tubería con Equipo de RadioDetección. | F25: 15000 | G25: 18300 | H25: =IF(Tabla1[[#This Row],[Codigo_actividad]]<>2.5,IF(((Tabla1[[#This Row],[fin]]-Tabla1[[#This Row],[inicio]])/1000)=0,"",((Tabla1[[#This Row],[fin]]-Tabla1[[#This Row],[inicio]])/1000)),"") -> 3.3 | J25: 2.6 | K25: =IF(_xlfn.XLOOKUP($J25,Catalogo!$B$7:$B$210,Catalogo!$I$7:$I$210,"",0)=0,"",_xlfn.XLOOKUP($J25,Catalogo!$B$7:$B$210,Catalogo!$I$7:$I$210,"",0)) -> Localizacion | L25: 25.4 | M25: =IF(Tabla1[[#This Row],[Avance_km]]<>"",Tabla1[[#This Row],[Avance_km]],Tabla1[[#This Row],[Avance_Med]])*_xlfn.XLOOKUP(Tabla1[[#This Row],[Codigo_actividad]],Catalogo!$B$6:$B$51,Catalogo!$F$6:$F$51,0) -> 7449.486
A26: 45980 | B26: C | C26: LIRA_GALERAS | D26: AC 8-6-4 in La Lira-Galeras | E26: Resistividades pH BRS BPA | F26: 0 | G26: 4500 | H26: =IF(Tabla1[[#This Row],[Codigo_actividad]]<>2.5,IF(((Tabla1[[#This Row],[fin]]-Tabla1[[#This Row],[inicio]])/1000)=0,"",((Tabla1[[#This Row],[fin]]-Tabla1[[#This Row],[inicio]])/1000)),"") | I26: 9 | J26: 2.5 | K26: =IF(_xlfn.XLOOKUP($J26,Catalogo!$B$7:$B$210,Catalogo!$I$7:$I$210,"",0)=0,"",_xlfn.XLOOKUP($J26,Catalogo!$B$7:$B$210,Catalogo!$I$7:$I$210,"",0)) -> Resistividades pH BSR BPA | L26: 31.54 | M26: =IF(Tabla1[[#This Row],[Avance_km]]<>"",Tabla1[[#This Row],[Avance_km]],Tabla1[[#This Row],[Avance_Med]])*_xlfn.XLOOKUP(Tabla1[[#This Row],[Codigo_actividad]],Catalogo!$B$6:$B$51,Catalogo!$F$6:$F$51,0) -> 41922
A27: 45981 | B27: A | C27: LIRA_GALERAS | D27: AC 8-6-4 in La Lira-Galeras | E27: Close Interval Survey CIS | F27: 15000 | G27: 18500 | H27: =IF(Tabla1[[#This Row],[Codigo_actividad]]<>2.5,IF(((Tabla1[[#This Row],[fin]]-Tabla1[[#This Row],[inicio]])/1000)=0,"",((Tabla1[[#This Row],[fin]]-Tabla1[[#This Row],[inicio]])/1000)),"") -> 3.5 | J27: 2.1 | K27: =IF(_xlfn.XLOOKUP($J27,Catalogo!$B$7:$B$210,Catalogo!$I$7:$I$210,"",0)=0,"",_xlfn.XLOOKUP($J27,Catalogo!$B$7:$B$210,Catalogo!$I$7:$I$210,"",0)) -> CIPS | L27: 31.54 | M27: =IF(Tabla1[[#This Row],[Avance_km]]<>"",Tabla1[[#This Row],[Avance_km]],Tabla1[[#This Row],[Avance_Med]])*_xlfn.XLOOKUP(Tabla1[[#This Row],[Codigo_actividad]],Catalogo!$B$6:$B$51,Catalogo!$F$6:$F$51,0) -> 50824.935
A28: 45981 | B28: B | C28: PECO_AGROS | D28: PECO II - GALERAS 10 | E28: Localización de Tubería con Equipo de RadioDetección. | F28: 18300 | G28: 25000 | H28: =IF(Tabla1[[#This Row],[Codigo_actividad]]<>2.5,IF(((Tabla1[[#This Row],[fin]]-Tabla1[[#This Row],[inicio]])/1000)=0,"",((Tabla1[[#This Row],[fin]]-Tabla1[[#This Row],[inicio]])/1000)),"") -> 6.7 | J28: 2.6 | K28: =IF(_xlfn.XLOOKUP($J28,Catalogo!$B$7:$B$210,Catalogo!$I$7:$I$210,"",0)=0,"",_xlfn.XLOOKUP($J28,Catalogo!$B$7:$B$210,Catalogo!$I$7:$I$210,"",0)) -> Localizacion | L28: 25.4 | M28: =IF(Tabla1[[#This Row],[Avance_km]]<>"",Tabla1[[#This Row],[Avance_km]],Tabla1[[#This Row],[Avance_Med]])*_xlfn.XLOOKUP(Tabla1[[#This Row],[Codigo_actividad]],Catalogo!$B$6:$B$51,Catalogo!$F$6:$F$51,0) -> 15124.714
A29: 45981 | B29: C | C29: LIRA_GALERAS | D29: AC 8-6-4 in La Lira-Galeras | E29: Resistividades pH BRS BPA | F29: 4500 | G29: 10000 | H29: =IF(Tabla1[[#This Row],[Codigo_actividad]]<>2.5,IF(((Tabla1[[#This Row],[fin]]-Tabla1[[#This Row],[inicio]])/1000)=0,"",((Tabla1[[#This Row],[fin]]-Tabla1[[#This Row],[inicio]])/1000)),"") | I29: 12 | J29: 2.5 | K29: =IF(_xlfn.XLOOKUP($J29,Catalogo!$B$7:$B$210,Catalogo!$I$7:$I$210,"",0)=0,"",_xlfn.XLOOKUP($J29,Catalogo!$B$7:$B$210,Catalogo!$I$7:$I$210,"",0)) -> Resistividades pH BSR BPA | L29: 31.54 | M29: =IF(Tabla1[[#This Row],[Avance_km]]<>"",Tabla1[[#This Row],[Avance_km]],Tabla1[[#This Row],[Avance_Med]])*_xlfn.XLOOKUP(Tabla1[[#This Row],[Codigo_actividad]],Catalogo!$B$6:$B$51,Catalogo!$F$6:$F$51,0) -> 55896
A30: 45982 | B30: A | C30: LIRA_GALERAS | D30: AC 8-6-4 in La Lira-Galeras | E30: Close Interval Survey CIS | F30: 18500 | G30: 24000 | H30: =IF(Tabla1[[#This Row],[Codigo_actividad]]<>2.5,IF(((Tabla1[[#This Row],[fin]]-Tabla1[[#This Row],[inicio]])/1000)=0,"",((Tabla1[[#This Row],[fin]]-Tabla1[[#This Row],[inicio]])/1000)),"") -> 5.5 | J30: 2.1 | K30: =IF(_xlfn.XLOOKUP($J30,Catalogo!$B$7:$B$210,Catalogo!$I$7:$I$210,"",0)=0,"",_xlfn.XLOOKUP($J30,Catalogo!$B$7:$B$210,Catalogo!$I$7:$I$210,"",0)) -> CIPS | L30: 31.54 | M30: =IF(Tabla1[[#This Row],[Avance_km]]<>"",Tabla1[[#This Row],[Avance_km]],Tabla1[[#This Row],[Avance_Med]])*_xlfn.XLOOKUP(Tabla1[[#This Row],[Codigo_actividad]],Catalogo!$B$6:$B$51,Catalogo!$F$6:$F$51,0) -> 79867.755
A31: 45982 | B31: B | C31: PECO_AGROS | D31: PECO II - GALERAS 10 | E31: Localización de Tubería con Equipo de RadioDetección. | F31: 25000 | G31: 25400 | H31: =IF(Tabla1[[#This Row],[Codigo_actividad]]<>2.5,IF(((Tabla1[[#This Row],[fin]]-Tabla1[[#This Row],[inicio]])/1000)=0,"",((Tabla1[[#This Row],[fin]]-Tabla1[[#This Row],[inicio]])/1000)),"") -> 0.4 | J31: 2.6 | K31: =IF(_xlfn.XLOOKUP($J31,Catalogo!$B$7:$B$210,Catalogo!$I$7:$I$210,"",0)=0,"",_xlfn.XLOOKUP($J31,Catalogo!$B$7:$B$210,Catalogo!$I$7:$I$210,"",0)) -> Localizacion | L31: 25.4 | M31: =IF(Tabla1[[#This Row],[Avance_km]]<>"",Tabla1[[#This Row],[Avance_km]],Tabla1[[#This Row],[Avance_Med]])*_xlfn.XLOOKUP(Tabla1[[#This Row],[Codigo_actividad]],Catalogo!$B$6:$B$51,Catalogo!$F$6:$F$51,0) -> 902.968
A32: 45982 | B32: B | C32: PECO_AGROS | D32: ED AGROPARK II (GAS PRIMO) | E32: Localización de Tubería con Equipo de RadioDetección. | F32: 0 | G32: 9 | H32: =IF(Tabla1[[#This Row],[Codigo_actividad]]<>2.5,IF(((Tabla1[[#This Row],[fin]]-Tabla1[[#This Row],[inicio]])/1000)=0,"",((Tabla1[[#This Row],[fin]]-Tabla1[[#This Row],[inicio]])/1000)),"") -> 0.009 | J32: 2.6 | K32: =IF(_xlfn.XLOOKUP($J32,Catalogo!$B$7:$B$210,Catalogo!$I$7:$I$210,"",0)=0,"",_xlfn.XLOOKUP($J32,Catalogo!$B$7:$B$210,Catalogo!$I$7:$I$210,"",0)) -> Localizacion | L32: 0.009 | M32: =IF(Tabla1[[#This Row],[Avance_km]]<>"",Tabla1[[#This Row],[Avance_km]],Tabla1[[#This Row],[Avance_Med]])*_xlfn.XLOOKUP(Tabla1[[#This Row],[Codigo_actividad]],Catalogo!$B$6:$B$51,Catalogo!$F$6:$F$51,0) -> 20.31678
A33: 45982 | B33: B | C33: PECO_AGROS | D33: LA BONITA | E33: Localización de Tubería con Equipo de RadioDetección. | F33: 0 | G33: 479 | H33: =IF(Tabla1[[#This Row],[Codigo_actividad]]<>2.5,IF(((Tabla1[[#This Row],[fin]]-Tabla1[[#This Row],[inicio]])/1000)=0,"",((Tabla1[[#This Row],[fin]]-Tabla1[[#This Row],[inicio]])/1000)),"") -> 0.479 | J33: 2.6 | K33: =IF(_xlfn.XLOOKUP($J33,Catalogo!$B$7:$B$210,Catalogo!$I$7:$I$210,"",0)=0,"",_xlfn.XLOOKUP($J33,Catalogo!$B$7:$B$210,Catalogo!$I$7:$I$210,"",0)) -> Localizacion | L33: 0.479 | M33: =IF(Tabla1[[#This Row],[Avance_km]]<>"",Tabla1[[#This Row],[Avance_km]],Tabla1[[#This Row],[Avance_Med]])*_xlfn.XLOOKUP(Tabla1[[#This Row],[Codigo_actividad]],Catalogo!$B$6:$B$51,Catalogo!$F$6:$F$51,0) -> 1081.3042
A34: 45982 | B34: C | C34: LIRA_GALERAS | D34: AC 8-6-4 in La Lira-Galeras | E34: Resistividades pH BRS BPA | F34: 10000 | G34: 15000 | H34: =IF(Tabla1[[#This Row],[Codigo_actividad]]<>2.5,IF(((Tabla1[[#This Row],[fin]]-Tabla1[[#This Row],[inicio]])/1000)=0,"",((Tabla1[[#This Row],[fin]]-Tabla1[[#This Row],[inicio]])/1000)),"") | I34: 11 | J34: 2.5 | K34: =IF(_xlfn.XLOOKUP($J34,Catalogo!$B$7:$B$210,Catalogo!$I$7:$I$210,"",0)=0,"",_xlfn.XLOOKUP($J34,Catalogo!$B$7:$B$210,Catalogo!$I$7:$I$210,"",0)) -> Resistividades pH BSR BPA | L34: 31.54 | M34: =IF(Tabla1[[#This Row],[Avance_km]]<>"",Tabla1[[#This Row],[Avance_km]],Tabla1[[#This Row],[Avance_Med]])*_xlfn.XLOOKUP(Tabla1[[#This Row],[Codigo_actividad]],Catalogo!$B$6:$B$51,Catalogo!$F$6:$F$51,0) -> 51238
A35: 45983 | B35: A | C35: LIRA_GALERAS | D35: AC 8-6-4 in La Lira-Galeras | E35: Close Interval Survey CIS | F35: 24000 | G35: 28500 | H35: =IF(Tabla1[[#This Row],[Codigo_actividad]]<>2.5,IF(((Tabla1[[#This Row],[fin]]-Tabla1[[#This Row],[inicio]])/1000)=0,"",((Tabla1[[#This Row],[fin]]-Tabla1[[#This Row],[inicio]])/1000)),"") -> 4.5 | J35: 2.1 | K35: =IF(_xlfn.XLOOKUP($J35,Catalogo!$B$7:$B$210,Catalogo!$I$7:$I$210,"",0)=0,"",_xlfn.XLOOKUP($J35,Catalogo!$B$7:$B$210,Catalogo!$I$7:$I$210,"",0)) -> CIPS | M35: =IF(Tabla1[[#This Row],[Avance_km]]<>"",Tabla1[[#This Row],[Avance_km]],Tabla1[[#This Row],[Avance_Med]])*_xlfn.XLOOKUP(Tabla1[[#This Row],[Codigo_actividad]],Catalogo!$B$6:$B$51,Catalogo!$F$6:$F$51,0) -> 65346.345
A36: 45983 | B36: A | C36: PECO_AGROS | D36: ERM FH FIBRAS | E36: Localización de Tubería con Equipo de RadioDetección. | F36: 0 | G36: 40 | H36: =IF(Tabla1[[#This Row],[Codigo_actividad]]<>2.5,IF(((Tabla1[[#This Row],[fin]]-Tabla1[[#This Row],[inicio]])/1000)=0,"",((Tabla1[[#This Row],[fin]]-Tabla1[[#This Row],[inicio]])/1000)),"") -> 0.04 | J36: 2.6 | K36: =IF(_xlfn.XLOOKUP($J36,Catalogo!$B$7:$B$210,Catalogo!$I$7:$I$210,"",0)=0,"",_xlfn.XLOOKUP($J36,Catalogo!$B$7:$B$210,Catalogo!$I$7:$I$210,"",0)) -> Localizacion | L36: 0.04 | M36: =IF(Tabla1[[#This Row],[Avance_km]]<>"",Tabla1[[#This Row],[Avance_km]],Tabla1[[#This Row],[Avance_Med]])*_xlfn.XLOOKUP(Tabla1[[#This Row],[Codigo_actividad]],Catalogo!$B$6:$B$51,Catalogo!$F$6:$F$51,0) -> 90.2968
A37: 45983 | B37: A | C37: PECO_AGROS | D37: ERM DESHITEC | E37: Localización de Tubería con Equipo de RadioDetección. | F37: 0 | G37: 120 | H37: =IF(Tabla1[[#This Row],[Codigo_actividad]]<>2.5,IF(((Tabla1[[#This Row],[fin]]-Tabla1[[#This Row],[inicio]])/1000)=0,"",((Tabla1[[#This Row],[fin]]-Tabla1[[#This Row],[inicio]])/1000)),"") -> 0.12 | J37: 2.6 | K37: =IF(_xlfn.XLOOKUP($J37,Catalogo!$B$7:$B$210,Catalogo!$I$7:$I$210,"",0)=0,"",_xlfn.XLOOKUP($J37,Catalogo!$B$7:$B$210,Catalogo!$I$7:$I$210,"",0)) -> Localizacion | L37: 0.12 | M37: =IF(Tabla1[[#This Row],[Avance_km]]<>"",Tabla1[[#This Row],[Avance_km]],Tabla1[[#This Row],[Avance_Med]])*_xlfn.XLOOKUP(Tabla1[[#This Row],[Codigo_actividad]],Catalogo!$B$6:$B$51,Catalogo!$F$6:$F$51,0) -> 270.8904
A38: 45983 | B38: B | C38: PECO_AGROS | D38: ED ARKANSAS | E38: Localización de Tubería con Equipo de RadioDetección. | F38: 0 | G38: 1195 | H38: =IF(Tabla1[[#This Row],[Codigo_actividad]]<>2.5,IF(((Tabla1[[#This Row],[fin]]-Tabla1[[#This Row],[inicio]])/1000)=0,"",((Tabla1[[#This Row],[fin]]-Tabla1[[#This Row],[inicio]])/1000)),"") -> 1.195 | J38: 2.6 | K38: =IF(_xlfn.XLOOKUP($J38,Catalogo!$B$7:$B$210,Catalogo!$I$7:$I$210,"",0)=0,"",_xlfn.XLOOKUP($J38,Catalogo!$B$7:$B$210,Catalogo!$I$7:$I$210,"",0)) -> Localizacion | L38: 1.195 | M38: =IF(Tabla1[[#This Row],[Avance_km]]<>"",Tabla1[[#This Row],[Avance_km]],Tabla1[[#This Row],[Avance_Med]])*_xlfn.XLOOKUP(Tabla1[[#This Row],[Codigo_actividad]],Catalogo!$B$6:$B$51,Catalogo!$F$6:$F$51,0) -> 2697.6169
A39: 45984 | B39: A | C39: LIRA_GALERAS | D39: AC 8-6-4 in La Lira-Galeras | E39: Close Interval Survey CIS | F39: 28500 | G39: 31540 | H39: =IF(Tabla1[[#This Row],[Codigo_actividad]]<>2.5,IF(((Tabla1[[#This Row],[fin]]-Tabla1[[#This Row],[inicio]])/1000)=0,"",((Tabla1[[#This Row],[fin]]-Tabla1[[#This Row],[inicio]])/1000)),"") -> 3.04 | J39: 2.1 | K39: =IF(_xlfn.XLOOKUP($J39,Catalogo!$B$7:$B$210,Catalogo!$I$7:$I$210,"",0)=0,"",_xlfn.XLOOKUP($J39,Catalogo!$B$7:$B$210,Catalogo!$I$7:$I$210,"",0)) -> CIPS | L39: 31.54 | M39: =IF(Tabla1[[#This Row],[Avance_km]]<>"",Tabla1[[#This Row],[Avance_km]],Tabla1[[#This Row],[Avance_Med]])*_xlfn.XLOOKUP(Tabla1[[#This Row],[Codigo_actividad]],Catalogo!$B$6:$B$51,Catalogo!$F$6:$F$51,0) -> 44145.086
A40: 45985 | B40: A | C40: LIRA_GALERAS | D40: AC 8-6-4 in La Lira-Galeras | E40: Direct Current Voltage Gradient DCVG | F40: 9000 | G40: 12000 | H40: =IF(Tabla1[[#This Row],[Codigo_actividad]]<>2.5,IF(((Tabla1[[#This Row],[fin]]-Tabla1[[#This Row],[inicio]])/1000)=0,"",((Tabla1[[#This Row],[fin]]-Tabla1[[#This Row],[inicio]])/1000)),"") -> 3 | J40: 2.3 | K40: =IF(_xlfn.XLOOKUP($J40,Catalogo!$B$7:$B$210,Catalogo!$I$7:$I$210,"",0)=0,"",_xlfn.XLOOKUP($J40,Catalogo!$B$7:$B$210,Catalogo!$I$7:$I$210,"",0)) -> DCVG | L40: 31.54 | M40: =IF(Tabla1[[#This Row],[Avance_km]]<>"",Tabla1[[#This Row],[Avance_km]],Tabla1[[#This Row],[Avance_Med]])*_xlfn.XLOOKUP(Tabla1[[#This Row],[Codigo_actividad]],Catalogo!$B$6:$B$51,Catalogo!$F$6:$F$51,0) -> 40666.89
A41: 45985 | B41: B | C41: LIRA_GALERAS | D41: VIBORILLAS | E41: Localización de Tubería con Equipo de RadioDetección. | F41: 0 | G41: 1488 | H41: =IF(Tabla1[[#This Row],[Codigo_actividad]]<>2.5,IF(((Tabla1[[#This Row],[fin]]-Tabla1[[#This Row],[inicio]])/1000)=0,"",((Tabla1[[#This Row],[fin]]-Tabla1[[#This Row],[inicio]])/1000)),"") -> 1.488 | J41: 2.6 | K41: =IF(_xlfn.XLOOKUP($J41,Catalogo!$B$7:$B$210,Catalogo!$I$7:$I$210,"",0)=0,"",_xlfn.XLOOKUP($J41,Catalogo!$B$7:$B$210,Catalogo!$I$7:$I$210,"",0)) -> Localizacion | L41: 1.488 | M41: =IF(Tabla1[[#This Row],[Avance_km]]<>"",Tabla1[[#This Row],[Avance_km]],Tabla1[[#This Row],[Avance_Med]])*_xlfn.XLOOKUP(Tabla1[[#This Row],[Codigo_actividad]],Catalogo!$B$6:$B$51,Catalogo!$F$6:$F$51,0) -> 3359.041
A42: 45985 | B42: B | C42: LIRA_GALERAS | D42: ERM VIBORILLAS | E42: Localización de Tubería con Equipo de RadioDetección. | F42: 0 | G42: 7 | H42: =IF(Tabla1[[#This Row],[Codigo_actividad]]<>2.5,IF(((Tabla1[[#This Row],[fin]]-Tabla1[[#This Row],[inicio]])/1000)=0,"",((Tabla1[[#This Row],[fin]]-Tabla1[[#This Row],[inicio]])/1000)),"") -> 0.007 | J42: 2.6 | K42: =IF(_xlfn.XLOOKUP($J42,Catalogo!$B$7:$B$210,Catalogo!$I$7:$I$210,"",0)=0,"",_xlfn.XLOOKUP($J42,Catalogo!$B$7:$B$210,Catalogo!$I$7:$I$210,"",0)) -> Localizacion | L42: 0.007 | M42: =IF(Tabla1[[#This Row],[Avance_km]]<>"",Tabla1[[#This Row],[Avance_km]],Tabla1[[#This Row],[Avance_Med]])*_xlfn.XLOOKUP(Tabla1[[#This Row],[Codigo_actividad]],Catalogo!$B$6:$B$51,Catalogo!$F$6:$F$51,0) -> 15.80194
A43: 45985 | B43: B | C43: LIRA_GALERAS | D43: ED BOMBARDIER | E43: Localización de Tubería con Equipo de RadioDetección. | F43: 0 | G43: 1855 | H43: =IF(Tabla1[[#This Row],[Codigo_actividad]]<>2.5,IF(((Tabla1[[#This Row],[fin]]-Tabla1[[#This Row],[inicio]])/1000)=0,"",((Tabla1[[#This Row],[fin]]-Tabla1[[#This Row],[inicio]])/1000)),"") -> 1.855 | J43: 2.6 | K43: =IF(_xlfn.XLOOKUP($J43,Catalogo!$B$7:$B$210,Catalogo!$I$7:$I$210,"",0)=0,"",_xlfn.XLOOKUP($J43,Catalogo!$B$7:$B$210,Catalogo!$I$7:$I$210,"",0)) -> Localizacion | L43: 1.855 | M43: =IF(Tabla1[[#This Row],[Avance_km]]<>"",Tabla1[[#This Row],[Avance_km]],Tabla1[[#This Row],[Avance_Med]])*_xlfn.XLOOKUP(Tabla1[[#This Row],[Codigo_actividad]],Catalogo!$B$6:$B$51,Catalogo!$F$6:$F$51,0) -> 4187.5141
A44: 45985 | B44: C | C44: LIRA_GALERAS | D44: AC 8-6-4 in La Lira-Galeras | E44: Resistividades pH BRS BPA | F44: 15000 | G44: 18500 | H44: =IF(Tabla1[[#This Row],[Codigo_actividad]]<>2.5,IF(((Tabla1[[#This Row],[fin]]-Tabla1[[#This Row],[inicio]])/1000)=0,"",((Tabla1[[#This Row],[fin]]-Tabla1[[#This Row],[inicio]])/1000)),"") | I44: 6 | J44: 2.5 | K44: =IF(_xlfn.XLOOKUP($J44,Catalogo!$B$7:$B$210,Catalogo!$I$7:$I$210,"",0)=0,"",_xlfn.XLOOKUP($J44,Catalogo!$B$7:$B$210,Catalogo!$I$7:$I$210,"",0)) -> Resistividades pH BSR BPA | L44: 31.54 | M44: =IF(Tabla1[[#This Row],[Avance_km]]<>"",Tabla1[[#This Row],[Avance_km]],Tabla1[[#This Row],[Avance_Med]])*_xlfn.XLOOKUP(Tabla1[[#This Row],[Codigo_actividad]],Catalogo!$B$6:$B$51,Catalogo!$F$6:$F$51,0) -> 27948
A45: 45986 | B45: A | C45: LIRA_GALERAS | D45: AC 8-6-4 in La Lira-Galeras | E45: Direct Current Voltage Gradient DCVG | F45: 0 | G45: 5000 | H45: =IF(Tabla1[[#This Row],[Codigo_actividad]]<>2.5,IF(((Tabla1[[#This Row],[fin]]-Tabla1[[#This Row],[inicio]])/1000)=0,"",((Tabla1[[#This Row],[fin]]-Tabla1[[#This Row],[inicio]])/1000)),"") -> 5 | J45: 2.3 | K45: =IF(_xlfn.XLOOKUP($J45,Catalogo!$B$7:$B$210,Catalogo!$I$7:$I$210,"",0)=0,"",_xlfn.XLOOKUP($J45,Catalogo!$B$7:$B$210,Catalogo!$I$7:$I$210,"",0)) -> DCVG | L45: 31.54 | M45: =IF(Tabla1[[#This Row],[Avance_km]]<>"",Tabla1[[#This Row],[Avance_km]],Tabla1[[#This Row],[Avance_Med]])*_xlfn.XLOOKUP(Tabla1[[#This Row],[Codigo_actividad]],Catalogo!$B$6:$B$51,Catalogo!$F$6:$F$51,0) -> 67778.15
A46: 45986 | B46: B | C46: LIRA_GALERAS | D46: AC 8-6-4 in La Lira-Galeras | E46: Direct Current Voltage Gradient DCVG | F46: 5000 | G46: 9000 | H46: =IF(Tabla1[[#This Row],[Codigo_actividad]]<>2.5,IF(((Tabla1[[#This Row],[fin]]-Tabla1[[#This Row],[inicio]])/1000)=0,"",((Tabla1[[#This Row],[fin]]-Tabla1[[#This Row],[inicio]])/1000)),"") -> 4 | J46: 2.3 | K46: =IF(_xlfn.XLOOKUP($J46,Catalogo!$B$7:$B$210,Catalogo!$I$7:$I$210,"",0)=0,"",_xlfn.XLOOKUP($J46,Catalogo!$B$7:$B$210,Catalogo!$I$7:$I$210,"",0)) -> DCVG | L46: 31.54 | M46: =IF(Tabla1[[#This Row],[Avance_km]]<>"",Tabla1[[#This Row],[Avance_km]],Tabla1[[#This Row],[Avance_Med]])*_xlfn.XLOOKUP(Tabla1[[#This Row],[Codigo_actividad]],Catalogo!$B$6:$B$51,Catalogo!$F$6:$F$51,0) -> 54222.52
A47: 45986 | B47: C | C47: LIRA_GALERAS | D47: AC 8-6-4 in La Lira-Galeras | E47: Resistividades pH BRS BPA | F47: 18500 | G47: 24500 | H47: =IF(Tabla1[[#This Row],[Codigo_actividad]]<>2.5,IF(((Tabla1[[#This Row],[fin]]-Tabla1[[#This Row],[inicio]])/1000)=0,"",((Tabla1[[#This Row],[fin]]-Tabla1[[#This Row],[inicio]])/1000)),"") | I47: 10 | J47: 2.5 | K47: =IF(_xlfn.XLOOKUP($J47,Catalogo!$B$7:$B$210,Catalogo!$I$7:$I$210,"",0)=0,"",_xlfn.XLOOKUP($J47,Catalogo!$B$7:$B$210,Catalogo!$I$7:$I$210,"",0)) -> Resistividades pH BSR BPA | L47: 31.54 | M47: =IF(Tabla1[[#This Row],[Avance_km]]<>"",Tabla1[[#This Row],[Avance_km]],Tabla1[[#This Row],[Avance_Med]])*_xlfn.XLOOKUP(Tabla1[[#This Row],[Codigo_actividad]],Catalogo!$B$6:$B$51,Catalogo!$F$6:$F$51,0) -> 46580
A48: 45987 | B48: A | C48: LIRA_GALERAS | D48: AC 8-6-4 in La Lira-Galeras | E48: Direct Current Voltage Gradient DCVG | F48: 18000 | G48: 24000 | H48: =IF(Tabla1[[#This Row],[Codigo_actividad]]<>2.5,IF(((Tabla1[[#This Row],[fin]]-Tabla1[[#This Row],[inicio]])/1000)=0,"",((Tabla1[[#This Row],[fin]]-Tabla1[[#This Row],[inicio]])/1000)),"") -> 6 | J48: 2.3 | K48: =IF(_xlfn.XLOOKUP($J48,Catalogo!$B$7:$B$210,Catalogo!$I$7:$I$210,"",0)=0,"",_xlfn.XLOOKUP($J48,Catalogo!$B$7:$B$210,Catalogo!$I$7:$I$210,"",0)) -> DCVG | L48: 31.54 | M48: =IF(Tabla1[[#This Row],[Avance_km]]<>"",Tabla1[[#This Row],[Avance_km]],Tabla1[[#This Row],[Avance_Med]])*_xlfn.XLOOKUP(Tabla1[[#This Row],[Codigo_actividad]],Catalogo!$B$6:$B$51,Catalogo!$F$6:$F$51,0) -> 81333.78
A49: 45987 | B49: B | C49: LIRA_GALERAS | D49: AC 8-6-4 in La Lira-Galeras | E49: Direct Current Voltage Gradient DCVG | F49: 12000 | G49: 18000 | H49: =IF(Tabla1[[#This Row],[Codigo_actividad]]<>2.5,IF(((Tabla1[[#This Row],[fin]]-Tabla1[[#This Row],[inicio]])/1000)=0,"",((Tabla1[[#This Row],[fin]]-Tabla1[[#This Row],[inicio]])/1000)),"") -> 6 | J49: 2.3 | K49: =IF(_xlfn.XLOOKUP($J49,Catalogo!$B$7:$B$210,Catalogo!$I$7:$I$210,"",0)=0,"",_xlfn.XLOOKUP($J49,Catalogo!$B$7:$B$210,Catalogo!$I$7:$I$210,"",0)) -> DCVG | L49: 31.54 | M49: =IF(Tabla1[[#This Row],[Avance_km]]<>"",Tabla1[[#This Row],[Avance_km]],Tabla1[[#This Row],[Avance_Med]])*_xlfn.XLOOKUP(Tabla1[[#This Row],[Codigo_actividad]],Catalogo!$B$6:$B$51,Catalogo!$F$6:$F$51,0) -> 81333.78
A50: 45987 | B50: C | C50: LIRA_GALERAS | D50: AC 8-6-4 in La Lira-Galeras | E50: Resistividades pH BRS BPA | F50: 24500 | G50: 30000 | H50: =IF(Tabla1[[#This Row],[Codigo_actividad]]<>2.5,IF(((Tabla1[[#This Row],[fin]]-Tabla1[[#This Row],[inicio]])/1000)=0,"",((Tabla1[[#This Row],[fin]]-Tabla1[[#This Row],[inicio]])/1000)),"") | I50: 12 | J50: 2.5 | K50: =IF(_xlfn.XLOOKUP($J50,Catalogo!$B$7:$B$210,Catalogo!$I$7:$I$210,"",0)=0,"",_xlfn.XLOOKUP($J50,Catalogo!$B$7:$B$210,Catalogo!$I$7:$I$210,"",0)) -> Resistividades pH BSR BPA | L50: 31.54 | M50: =IF(Tabla1[[#This Row],[Avance_km]]<>"",Tabla1[[#This Row],[Avance_km]],Tabla1[[#This Row],[Avance_Med]])*_xlfn.XLOOKUP(Tabla1[[#This Row],[Codigo_actividad]],Catalogo!$B$6:$B$51,Catalogo!$F$6:$F$51,0) -> 55896
H51: =IF(Tabla1[[#This Row],[Codigo_actividad]]<>2.5,IF(((Tabla1[[#This Row],[fin]]-Tabla1[[#This Row],[inicio]])/1000)=0,"",((Tabla1[[#This Row],[fin]]-Tabla1[[#This Row],[inicio]])/1000)),"") | K51: =IF(_xlfn.XLOOKUP($J51,Catalogo!$B$7:$B$210,Catalogo!$I$7:$I$210,"",0)=0,"",_xlfn.XLOOKUP($J51,Catalogo!$B$7:$B$210,Catalogo!$I$7:$I$210,"",0)) | M51: =IF(Tabla1[[#This Row],[Avance_km]]<>"",Tabla1[[#This Row],[Avance_km]],Tabla1[[#This Row],[Avance_Med]])*_xlfn.XLOOKUP(Tabla1[[#This Row],[Codigo_actividad]],Catalogo!$B$6:$B$51,Catalogo!$F$6:$F$51,0) -> 0
...

Sheet Resumen
A1: Sistema | B1: Nombre ducto | C1: Len | D1: Localizacion | E1: CIPS | F1: DCVG | G1: Resistividades pH BSR BPA | H1: ACVG | I1: PCM
A2: =+_xlfn.XLOOKUP(B2,Tabla1[Ducto],Tabla1[Sistema],"") -> LIRA_GALERAS | B2: {=_xlfn._xlws.FILTER(_xlfn.UNIQUE(Tabla1[Ducto]), _xlfn.UNIQUE(Tabla1[Ducto])<>0)} -> AC 8-6-4 in La Lira-Galeras | C2: =+_xlfn.XLOOKUP(B2,Tabla1[Ducto],Tabla1[Length]) -> 31.54 | D2: =IFERROR(SUMIFS(Tabla1[Avance_km],Tabla1[Ducto],Resumen!$B2,Tabla1[nombre_actividad],D$1)/$C2,0) -> 1 | E2: =IFERROR(SUMIFS(Tabla1[Avance_km],Tabla1[Ducto],Resumen!$B2,Tabla1[nombre_actividad],E$1)/$C2,0) -> 1 | F2: =IFERROR(SUMIFS(Tabla1[Avance_km],Tabla1[Ducto],Resumen!$B2,Tabla1[nombre_actividad],F$1)/$C2,0) -> 1 | G2: =IFERROR(SUMIFS(Tabla1[Avance_Med],Tabla1[Ducto],Resumen!$B2,Tabla1[nombre_actividad],G$1)/64,0) -> 1 | H2: =+SUMIFS(Tabla1[Avance_km],Tabla1[Ducto],Resumen!$B2,Tabla1[nombre_actividad],H$1)/$C2 -> 0 | I2: =+SUMIFS(Tabla1[Avance_km],Tabla1[Ducto],Resumen!$B2,Tabla1[nombre_actividad],I$1)/$C2 -> 0 | J2: =+_xlfn.XLOOKUP(B2,'R (s01)'!B:B,'R (s01)'!J:J) -> 0
A3: =+_xlfn.XLOOKUP(B3,Tabla1[Ducto],Tabla1[Sistema],"") -> LIRA_GALERAS | B3: ALESTRA | C3: =+_xlfn.XLOOKUP(B3,Tabla1[Ducto],Tabla1[Length]) -> 1.982 | D3: =IFERROR(SUMIFS(Tabla1[Avance_km],Tabla1[Ducto],Resumen!$B3,Tabla1[nombre_actividad],D$1)/$C3,0) -> 1 | E3: =IFERROR(SUMIFS(Tabla1[Avance_km],Tabla1[Ducto],Resumen!$B3,Tabla1[nombre_actividad],E$1)/$C3,0) -> 1 | F3: =IFERROR(SUMIFS(Tabla1[Avance_km],Tabla1[Ducto],Resumen!$B3,Tabla1[nombre_actividad],F$1)/$C3,0) -> 1 | G3: =IFERROR(SUMIFS(Tabla1[Avance_Med],Tabla1[Ducto],Resumen!$B3,Tabla1[nombre_actividad],G$1)/(ROUNDUP(C3,0)*2),0) -> 1 | H3: =+SUMIFS(Tabla1[Avance_km],Tabla1[Ducto],Resumen!$B3,Tabla1[nombre_actividad],H$1)/$C3 -> 0 | I3: =+SUMIFS(Tabla1[Avance_km],Tabla1[Ducto],Resumen!$B3,Tabla1[nombre_actividad],I$1)/$C3 -> 0 | J3: =+_xlfn.XLOOKUP(B3,'R (s01)'!B:B,'R (s01)'!J:J) -> 4
A4: =+_xlfn.XLOOKUP(B4,Tabla1[Ducto],Tabla1[Sistema],"") -> LIRA_GALERAS | B4: HUAWEI | C4: =+_xlfn.XLOOKUP(B4,Tabla1[Ducto],Tabla1[Length]) -> 0.175 | D4: =IFERROR(SUMIFS(Tabla1[Avance_km],Tabla1[Ducto],Resumen!$B4,Tabla1[nombre_actividad],D$1)/$C4,0) -> 1 | E4: =IFERROR(SUMIFS(Tabla1[Avance_km],Tabla1[Ducto],Resumen!$B4,Tabla1[nombre_actividad],E$1)/$C4,0) -> 1 | F4: =IFERROR(SUMIFS(Tabla1[Avance_km],Tabla1[Ducto],Resumen!$B4,Tabla1[nombre_actividad],F$1)/$C4,0) -> 1 | G4: =IFERROR(SUMIFS(Tabla1[Avance_Med],Tabla1[Ducto],Resumen!$B4,Tabla1[nombre_actividad],G$1)/(ROUNDUP(C4,0)*2),0) -> 1 | H4: =+SUMIFS(Tabla1[Avance_km],Tabla1[Ducto],Resumen!$B4,Tabla1[nombre_actividad],H$1)/$C4 -> 0 | I4: =+SUMIFS(Tabla1[Avance_km],Tabla1[Ducto],Resumen!$B4,Tabla1[nombre_actividad],I$1)/$C4 -> 0 | J4: =+_xlfn.XLOOKUP(B4,'R (s01)'!B:B,'R (s01)'!J:J) -> 2
A5: =+_xlfn.XLOOKUP(B5,Tabla1[Ducto],Tabla1[Sistema],"") -> LIRA_GALERAS | B5: ITASA | C5: =+_xlfn.XLOOKUP(B5,Tabla1[Ducto],Tabla1[Length]) -> 0.015 | D5: =IFERROR(SUMIFS(Tabla1[Avance_km],Tabla1[Ducto],Resumen!$B5,Tabla1[nombre_actividad],D$1)/$C5,0) -> 1 | E5: =IFERROR(SUMIFS(Tabla1[Avance_km],Tabla1[Ducto],Resumen!$B5,Tabla1[nombre_actividad],E$1)/$C5,0) -> 1 | F5: =IFERROR(SUMIFS(Tabla1[Avance_km],Tabla1[Ducto],Resumen!$B5,Tabla1[nombre_actividad],F$1)/$C5,0) -> 1 | H5: =+SUMIFS(Tabla1[Avance_km],Tabla1[Ducto],Resumen!$B5,Tabla1[nombre_actividad],H$1)/$C5 -> 0 | I5: =+SUMIFS(Tabla1[Avance_km],Tabla1[Ducto],Resumen!$B5,Tabla1[nombre_actividad],I$1)/$C5 -> 0 | J5: =+_xlfn.XLOOKUP(B5,'R (s01)'!B:B,'R (s01)'!J:J) -> 0
A6: =+_xlfn.XLOOKUP(B6,Tabla1[Ducto],Tabla1[Sistema],"") -> LIRA_GALERAS | B6: ED PARQUE INDUSTRIAL FINSA II | C6: =+_xlfn.XLOOKUP(B6,Tabla1[Ducto],Tabla1[Length]) -> 1.02 | D6: =IFERROR(SUMIFS(Tabla1[Avance_km],Tabla1[Ducto],Resumen!$B6,Tabla1[nombre_actividad],D$1)/$C6,0) -> 1 | E6: =IFERROR(SUMIFS(Tabla1[Avance_km],Tabla1[Ducto],Resumen!$B6,Tabla1[nombre_actividad],E$1)/$C6,0) -> 1 | F6: =IFERROR(SUMIFS(Tabla1[Avance_km],Tabla1[Ducto],Resumen!$B6,Tabla1[nombre_actividad],F$1)/$C6,0) -> 1 | G6: =IFERROR(SUMIFS(Tabla1[Avance_Med],Tabla1[Ducto],Resumen!$B6,Tabla1[nombre_actividad],G$1)/(3),0) -> 1 | H6: =+SUMIFS(Tabla1[Avance_km],Tabla1[Ducto],Resumen!$B6,Tabla1[nombre_actividad],H$1)/$C6 -> 0 | I6: =+SUMIFS(Tabla1[Avance_km],Tabla1[Ducto],Resumen!$B6,Tabla1[nombre_actividad],I$1)/$C6 -> 0 | J6: =+_xlfn.XLOOKUP(B6,'R (s01)'!B:B,'R (s01)'!J:J) -> 3
A7: =+_xlfn.XLOOKUP(B7,Tabla1[Ducto],Tabla1[Sistema],"") -> LIRA_GALERAS | B7: NUTRIBAQ | C7: =+_xlfn.XLOOKUP(B7,Tabla1[Ducto],Tabla1[Length]) -> 1.055 | D7: =IFERROR(SUMIFS(Tabla1[Avance_km],Tabla1[Ducto],Resumen!$B7,Tabla1[nombre_actividad],D$1)/$C7,0) -> 1 | E7: =IFERROR(SUMIFS(Tabla1[Avance_km],Tabla1[Ducto],Resumen!$B7,Tabla1[nombre_actividad],E$1)/$C7,0) -> 1 | F7: =IFERROR(SUMIFS(Tabla1[Avance_km],Tabla1[Ducto],Resumen!$B7,Tabla1[nombre_actividad],F$1)/$C7,0) -> 1 | G7: =IFERROR(SUMIFS(Tabla1[Avance_Med],Tabla1[Ducto],Resumen!$B7,Tabla1[nombre_actividad],G$1)/(3),0) -> 1 | H7: =+SUMIFS(Tabla1[Avance_km],Tabla1[Ducto],Resumen!$B7,Tabla1[nombre_actividad],H$1)/$C7 -> 0 | I7: =+SUMIFS(Tabla1[Avance_km],Tabla1[Ducto],Resumen!$B7,Tabla1[nombre_actividad],I$1)/$C7 -> 0 | J7: =+_xlfn.XLOOKUP(B7,'R (s01)'!B:B,'R (s01)'!J:J) -> 3
A8: =+_xlfn.XLOOKUP(B8,Tabla1[Ducto],Tabla1[Sistema],"") -> PECO_AGROS | B8: AGROS | C8: =+_xlfn.XLOOKUP(B8,Tabla1[Ducto],Tabla1[Length]) -> 2.2 | D8: =IFERROR(SUMIFS(Tabla1[Avance_km],Tabla1[Ducto],Resumen!$B8,Tabla1[nombre_actividad],D$1)/$C8,0) -> 1 | E8: =IFERROR(SUMIFS(Tabla1[Avance_km],Tabla1[Ducto],Resumen!$B8,Tabla1[nombre_actividad],E$1)/$C8,0) -> 1 | F8: =IFERROR(SUMIFS(Tabla1[Avance_km],Tabla1[Ducto],Resumen!$B8,Tabla1[nombre_actividad],F$1)/$C8,0) -> 1 | G8: =IFERROR(SUMIFS(Tabla1[Avance_Med],Tabla1[Ducto],Resumen!$B8,Tabla1[nombre_actividad],G$1)/(ROUNDUP(C8,0)*2),0) -> 1 | H8: =+SUMIFS(Tabla1[Avance_km],Tabla1[Ducto],Resumen!$B8,Tabla1[nombre_actividad],H$1)/$C8 -> 0 | I8: =+SUMIFS(Tabla1[Avance_km],Tabla1[Ducto],Resumen!$B8,Tabla1[nombre_actividad],I$1)/$C8 -> 0 | J8: =+_xlfn.XLOOKUP(B8,'R (s01)'!B:B,'R (s01)'!J:J) -> #N/A
A9: =+_xlfn.XLOOKUP(B9,Tabla1[Ducto],Tabla1[Sistema],"") -> PECO_AGROS | B9: SUNNY FIELDS | C9: =+_xlfn.XLOOKUP(B9,Tabla1[Ducto],Tabla1[Length]) -> 2.576 | D9: =IFERROR(SUMIFS(Tabla1[Avance_km],Tabla1[Ducto],Resumen!$B9,Tabla1[nombre_actividad],D$1)/$C9,0) -> 1 | E9: =IFERROR(SUMIFS(Tabla1[Avance_km],Tabla1[Ducto],Resumen!$B9,Tabla1[nombre_actividad],E$1)/$C9,0) -> 1 | F9: =IFERROR(SUMIFS(Tabla1[Avance_km],Tabla1[Ducto],Resumen!$B9,Tabla1[nombre_actividad],F$1)/$C9,0) -> 1 | G9: =IFERROR(SUMIFS(Tabla1[Avance_Med],Tabla1[Ducto],Resumen!$B9,Tabla1[nombre_actividad],G$1)/(ROUNDUP(C9,0)*2),0) -> 1 | H9: =+SUMIFS(Tabla1[Avance_km],Tabla1[Ducto],Resumen!$B9,Tabla1[nombre_actividad],H$1)/$C9 -> 0 | I9: =+SUMIFS(Tabla1[Avance_km],Tabla1[Ducto],Resumen!$B9,Tabla1[nombre_actividad],I$1)/$C9 -> 0 | J9: =+_xlfn.XLOOKUP(B9,'R (s01)'!B:B,'R (s01)'!J:J) -> #N/A
A10: =+_xlfn.XLOOKUP(B10,Tabla1[Ducto],Tabla1[Sistema],"") -> PECO_AGROS | B10: BEL GIARDINO | C10: =+_xlfn.XLOOKUP(B10,Tabla1[Ducto],Tabla1[Length]) -> 0.125 | D10: =IFERROR(SUMIFS(Tabla1[Avance_km],Tabla1[Ducto],Resumen!$B10,Tabla1[nombre_actividad],D$1)/$C10,0) -> 1 | E10: =IFERROR(SUMIFS(Tabla1[Avance_km],Tabla1[Ducto],Resumen!$B10,Tabla1[nombre_actividad],E$1)/$C10,0) -> 1 | F10: =IFERROR(SUMIFS(Tabla1[Avance_km],Tabla1[Ducto],Resumen!$B10,Tabla1[nombre_actividad],F$1)/$C10,0) -> 1 | H10: =+SUMIFS(Tabla1[Avance_km],Tabla1[Ducto],Resumen!$B10,Tabla1[nombre_actividad],H$1)/$C10 -> 0 | I10: =+SUMIFS(Tabla1[Avance_km],Tabla1[Ducto],Resumen!$B10,Tabla1[nombre_actividad],I$1)/$C10 -> 0 | J10: =+_xlfn.XLOOKUP(B10,'R (s01)'!B:B,'R (s01)'!J:J) -> #N/A
A11: =+_xlfn.XLOOKUP(B11,Tabla1[Ducto],Tabla1[Sistema],"") -> PECO_AGROS | B11: PRIME HASRVEST | C11: =+_xlfn.XLOOKUP(B11,Tabla1[Ducto],Tabla1[Length]) -> 0.741 | D11: =IFERROR(SUMIFS(Tabla1[Avance_km],Tabla1[Ducto],Resumen!$B11,Tabla1[nombre_actividad],D$1)/$C11,0) -> 1 | E11: =IFERROR(SUMIFS(Tabla1[Avance_km],Tabla1[Ducto],Resumen!$B11,Tabla1[nombre_actividad],E$1)/$C11,0) -> 1 | F11: =IFERROR(SUMIFS(Tabla1[Avance_km],Tabla1[Ducto],Resumen!$B11,Tabla1[nombre_actividad],F$1)/$C11,0) -> 1 | G11: =IFERROR(SUMIFS(Tabla1[Avance_Med],Tabla1[Ducto],Resumen!$B11,Tabla1[nombre_actividad],G$1)/(ROUNDUP(C11,0)*2),0) -> 1 | H11: =+SUMIFS(Tabla1[Avance_km],Tabla1[Ducto],Resumen!$B11,Tabla1[nombre_actividad],H$1)/$C11 -> 0 | I11: =+SUMIFS(Tabla1[Avance_km],Tabla1[Ducto],Resumen!$B11,Tabla1[nombre_actividad],I$1)/$C11 -> 0 | J11: =+_xlfn.XLOOKUP(B11,'R (s01)'!B:B,'R (s01)'!J:J) -> #N/A
A12: =+_xlfn.XLOOKUP(B12,Tabla1[Ducto],Tabla1[Sistema],"") -> PECO_AGROS | B12: PECO II - GALERAS 10 | C12: =+_xlfn.XLOOKUP(B12,Tabla1[Ducto],Tabla1[Length]) -> 25.4 | D12: =IFERROR(SUMIFS(Tabla1[Avance_km],Tabla1[Ducto],Resumen!$B12,Tabla1[nombre_actividad],D$1)/$C12,0) -> 1 | E12: =IFERROR(SUMIFS(Tabla1[Avance_km],Tabla1[Ducto],Resumen!$B12,Tabla1[nombre_actividad],E$1)/$C12,0) -> 1 | F12: =IFERROR(SUMIFS(Tabla1[Avance_km],Tabla1[Ducto],Resumen!$B12,Tabla1[nombre_actividad],F$1)/$C12,0) -> 1 | G12: =IFERROR(SUMIFS(Tabla1[Avance_Med],Tabla1[Ducto],Resumen!$B12,Tabla1[nombre_actividad],G$1)/52,0) -> 1 | H12: =+SUMIFS(Tabla1[Avance_km],Tabla1[Ducto],Resumen!$B12,Tabla1[nombre_actividad],H$1)/$C12 -> 0 | I12: =+SUMIFS(Tabla1[Avance_km],Tabla1[Ducto],Resumen!$B12,Tabla1[nombre_actividad],I$1)/$C12 -> 0 | J12: =+_xlfn.XLOOKUP(B12,'R (s01)'!B:B,'R (s01)'!J:J) -> #N/A
A13: =+_xlfn.XLOOKUP(B13,Tabla1[Ducto],Tabla1[Sistema],"") -> PECO_AGROS | B13: ED AGROPARK II (GAS PRIMO) | C13: =+_xlfn.XLOOKUP(B13,Tabla1[Ducto],Tabla1[Length]) -> 0.009 | D13: =IFERROR(SUMIFS(Tabla1[Avance_km],Tabla1[Ducto],Resumen!$B13,Tabla1[nombre_actividad],D$1)/$C13,0) -> 1 | E13: =IFERROR(SUMIFS(Tabla1[Avance_km],Tabla1[Ducto],Resumen!$B13,Tabla1[nombre_actividad],E$1)/$C13,0) -> 1 | F13: =IFERROR(SUMIFS(Tabla1[Avance_km],Tabla1[Ducto],Resumen!$B13,Tabla1[nombre_actividad],F$1)/$C13,0) -> 1 | G13: =IFERROR(SUMIFS(Tabla1[Avance_Med],Tabla1[Ducto],Resumen!$B13,Tabla1[nombre_actividad],G$1)/(1),0) -> 0 | H13: =+SUMIFS(Tabla1[Avance_km],Tabla1[Ducto],Resumen!$B13,Tabla1[nombre_actividad],H$1)/$C13 -> 0 | I13: =+SUMIFS(Tabla1[Avance_km],Tabla1[Ducto],Resumen!$B13,Tabla1[nombre_actividad],I$1)/$C13 -> 0 | J13: =+_xlfn.XLOOKUP(B13,'R (s01)'!B:B,'R (s01)'!J:J) -> #N/A
A14: =+_xlfn.XLOOKUP(B14,Tabla1[Ducto],Tabla1[Sistema],"") -> PECO_AGROS | B14: LA BONITA | C14: =+_xlfn.XLOOKUP(B14,Tabla1[Ducto],Tabla1[Length]) -> 0.479 | D14: =IFERROR(SUMIFS(Tabla1[Avance_km],Tabla1[Ducto],Resumen!$B14,Tabla1[nombre_actividad],D$1)/$C14,0) -> 1 | E14: =IFERROR(SUMIFS(Tabla1[Avance_km],Tabla1[Ducto],Resumen!$B14,Tabla1[nombre_actividad],E$1)/$C14,0) -> 1 | F14: =IFERROR(SUMIFS(Tabla1[Avance_km],Tabla1[Ducto],Resumen!$B14,Tabla1[nombre_actividad],F$1)/$C14,0) -> 1 | H14: =+SUMIFS(Tabla1[Avance_km],Tabla1[Ducto],Resumen!$B14,Tabla1[nombre_actividad],H$1)/$C14 -> 0 | I14: =+SUMIFS(Tabla1[Avance_km],Tabla1[Ducto],Resumen!$B14,Tabla1[nombre_actividad],I$1)/$C14 -> 0 | J14: =+_xlfn.XLOOKUP(B14,'R (s01)'!B:B,'R (s01)'!J:J) -> #N/A
A15: =+_xlfn.XLOOKUP(B15,Tabla1[Ducto],Tabla1[Sistema],"") -> PECO_AGROS | B15: ERM FH FIBRAS | C15: =+_xlfn.XLOOKUP(B15,Tabla1[Ducto],Tabla1[Length]) -> 0.04 | D15: =IFERROR(SUMIFS(Tabla1[Avance_km],Tabla1[Ducto],Resumen!$B15,Tabla1[nombre_actividad],D$1)/$C15,0) -> 1 | E15: =IFERROR(SUMIFS(Tabla1[Avance_km],Tabla1[Ducto],Resumen!$B15,Tabla1[nombre_actividad],E$1)/$C15,0) -> 1 | F15: =IFERROR(SUMIFS(Tabla1[Avance_km],Tabla1[Ducto],Resumen!$B15,Tabla1[nombre_actividad],F$1)/$C15,0) -> 1 | G15: =IFERROR(SUMIFS(Tabla1[Avance_Med],Tabla1[Ducto],Resumen!$B15,Tabla1[nombre_actividad],G$1)/(1),0) -> 0 | H15: =+SUMIFS(Tabla1[Avance_km],Tabla1[Ducto],Resumen!$B15,Tabla1[nombre_actividad],H$1)/$C15 -> 0 | I15: =+SUMIFS(Tabla1[Avance_km],Tabla1[Ducto],Resumen!$B15,Tabla1[nombre_actividad],I$1)/$C15 -> 0 | J15: =+_xlfn.XLOOKUP(B15,'R (s01)'!B:B,'R (s01)'!J:J) -> #N/A
A16: =+_xlfn.XLOOKUP(B16,Tabla1[Ducto],Tabla1[Sistema],"") -> PECO_AGROS | B16: ERM DESHITEC | C16: =+_xlfn.XLOOKUP(B16,Tabla1[Ducto],Tabla1[Length]) -> 0.12 | D16: =IFERROR(SUMIFS(Tabla1[Avance_km],Tabla1[Ducto],Resumen!$B16,Tabla1[nombre_actividad],D$1)/$C16,0) -> 1 | E16: =IFERROR(SUMIFS(Tabla1[Avance_km],Tabla1[Ducto],Resumen!$B16,Tabla1[nombre_actividad],E$1)/$C16,0) -> 1 | F16: =IFERROR(SUMIFS(Tabla1[Avance_km],Tabla1[Ducto],Resumen!$B16,Tabla1[nombre_actividad],F$1)/$C16,0) -> 1 | G16: =IFERROR(SUMIFS(Tabla1[Avance_Med],Tabla1[Ducto],Resumen!$B16,Tabla1[nombre_actividad],G$1)/(3),0) -> 0.33333333 | J16: =+_xlfn.XLOOKUP(B16,'R (s01)'!B:B,'R (s01)'!J:J) -> #N/A
A17: =+_xlfn.XLOOKUP(B17,Tabla1[Ducto],Tabla1[Sistema],"") -> PECO_AGROS | B17: ED ARKANSAS | C17: =+_xlfn.XLOOKUP(B17,Tabla1[Ducto],Tabla1[Length]) -> 1.195 | D17: =IFERROR(SUMIFS(Tabla1[Avance_km],Tabla1[Ducto],Resumen!$B17,Tabla1[nombre_actividad],D$1)/$C17,0) -> 1 | E17: =IFERROR(SUMIFS(Tabla1[Avance_km],Tabla1[Ducto],Resumen!$B17,Tabla1[nombre_actividad],E$1)/$C17,0) -> 1 | F17: =IFERROR(SUMIFS(Tabla1[Avance_km],Tabla1[Ducto],Resumen!$B17,Tabla1[nombre_actividad],F$1)/$C17,0) -> 1 | G17: =IFERROR(SUMIFS(Tabla1[Avance_Med],Tabla1[Ducto],Resumen!$B17,Tabla1[nombre_actividad],G$1)/(ROUNDUP(C17,0)*2),0) -> 0.75 | J17: =+_xlfn.XLOOKUP(B17,'R (s01)'!B:B,'R (s01)'!J:J) -> #N/A
A18: =+_xlfn.XLOOKUP(B18,Tabla1[Ducto],Tabla1[Sistema],"") -> LIRA_GALERAS | B18: VIBORILLAS | C18: =+_xlfn.XLOOKUP(B18,Tabla1[Ducto],Tabla1[Length]) -> 1.488 | D18: =IFERROR(SUMIFS(Tabla1[Avance_km],Tabla1[Ducto],Resumen!$B18,Tabla1[nombre_actividad],D$1)/$C18,0) -> 1 | E18: =IFERROR(SUMIFS(Tabla1[Avance_km],Tabla1[Ducto],Resumen!$B18,Tabla1[nombre_actividad],E$1)/$C18,0) -> 1 | F18: =IFERROR(SUMIFS(Tabla1[Avance_km],Tabla1[Ducto],Resumen!$B18,Tabla1[nombre_actividad],F$1)/$C18,0) -> 1 | G18: =IFERROR(SUMIFS(Tabla1[Avance_Med],Tabla1[Ducto],Resumen!$B18,Tabla1[nombre_actividad],G$1)/(ROUNDUP(C18,0)*2),0) -> 1 | J18: =+_xlfn.XLOOKUP(B18,'R (s01)'!B:B,'R (s01)'!J:J) -> 4
A19: =+_xlfn.XLOOKUP(B19,Tabla1[Ducto],Tabla1[Sistema],"") -> LIRA_GALERAS | B19: ERM VIBORILLAS | C19: =+_xlfn.XLOOKUP(B19,Tabla1[Ducto],Tabla1[Length]) -> 0.007 | D19: =IFERROR(SUMIFS(Tabla1[Avance_km],Tabla1[Ducto],Resumen!$B19,Tabla1[nombre_actividad],D$1)/$C19,0) -> 1 | E19: =IFERROR(SUMIFS(Tabla1[Avance_km],Tabla1[Ducto],Resumen!$B19,Tabla1[nombre_actividad],E$1)/$C19,0) -> 1 | F19: =IFERROR(SUMIFS(Tabla1[Avance_km],Tabla1[Ducto],Resumen!$B19,Tabla1[nombre_actividad],F$1)/$C19,0) -> 1 | G19: =IFERROR(SUMIFS(Tabla1[Avance_Med],Tabla1[Ducto],Resumen!$B19,Tabla1[nombre_actividad],G$1)/1,0) -> 0 | J19: =+_xlfn.XLOOKUP(B19,'R (s01)'!B:B,'R (s01)'!J:J) -> 0
A20: =+_xlfn.XLOOKUP(B20,Tabla1[Ducto],Tabla1[Sistema],"") -> LIRA_GALERAS | B20: ED BOMBARDIER | C20: =+_xlfn.XLOOKUP(B20,Tabla1[Ducto],Tabla1[Length]) -> 1.855 | D20: =IFERROR(SUMIFS(Tabla1[Avance_km],Tabla1[Ducto],Resumen!$B20,Tabla1[nombre_actividad],D$1)/$C20,0) -> 1 | E20: =IFERROR(SUMIFS(Tabla1[Avance_km],Tabla1[Ducto],Resumen!$B20,Tabla1[nombre_actividad],E$1)/$C20,0) -> 1 | F20: =IFERROR(SUMIFS(Tabla1[Avance_km],Tabla1[Ducto],Resumen!$B20,Tabla1[nombre_actividad],F$1)/$C20,0) -> 1 | G20: =IFERROR(SUMIFS(Tabla1[Avance_Med],Tabla1[Ducto],Resumen!$B20,Tabla1[nombre_actividad],G$1)/(1),0) -> 4 | J20: =+_xlfn.XLOOKUP(B20,'R (s01)'!B:B,'R (s01)'!J:J) -> 4
A21: =+_xlfn.XLOOKUP(B21,Tabla1[Ducto],Tabla1[Sistema],"") -> PECO_AGROS | B21: MOLINOS ANAHUAC | C21: =+_xlfn.XLOOKUP(B21,Tabla1[Ducto],Tabla1[Length]) -> 0.02 | D21: =IFERROR(SUMIFS(Tabla1[Avance_km],Tabla1[Ducto],Resumen!$B21,Tabla1[nombre_actividad],D$1)/$C21,0) -> 1 | E21: =IFERROR(SUMIFS(Tabla1[Avance_km],Tabla1[Ducto],Resumen!$B21,Tabla1[nombre_actividad],E$1)/$C21,0) -> 1 | F21: =IFERROR(SUMIFS(Tabla1[Avance_km],Tabla1[Ducto],Resumen!$B21,Tabla1[nombre_actividad],F$1)/$C21,0) -> 1 | J21: =+_xlfn.XLOOKUP(B21,'R (s01)'!B:B,'R (s01)'!J:J) -> #N/A
A22: =+_xlfn.XLOOKUP(B22,Tabla1[Ducto],Tabla1[Sistema],"") -> LIRA_GALERAS | B22: FRESHLLACA | C22: =+_xlfn.XLOOKUP(B22,Tabla1[Ducto],Tabla1[Length]) -> 0.02 | D22: =IFERROR(SUMIFS(Tabla1[Avance_km],Tabla1[Ducto],Resumen!$B22,Tabla1[nombre_actividad],D$1)/$C22,0) -> 1 | E22: =IFERROR(SUMIFS(Tabla1[Avance_km],Tabla1[Ducto],Resumen!$B22,Tabla1[nombre_actividad],E$1)/$C22,0) -> 1 | F22: =IFERROR(SUMIFS(Tabla1[Avance_km],Tabla1[Ducto],Resumen!$B22,Tabla1[nombre_actividad],F$1)/$C22,0) -> 1 | G22: =IFERROR(SUMIFS(Tabla1[Avance_Med],Tabla1[Ducto],Resumen!$B22,Tabla1[nombre_actividad],G$1)/(1),0) -> 1 | J22: =+_xlfn.XLOOKUP(B22,'R (s01)'!B:B,'R (s01)'!J:J) -> 1
A23: =+_xlfn.XLOOKUP(B23,Tabla1[Ducto],Tabla1[Sistema],"") -> LIRA_GALERAS | B23: RANCHO HUMUS | C23: =+_xlfn.XLOOKUP(B23,Tabla1[Ducto],Tabla1[Length]) -> 0.07 | D23: =IFERROR(SUMIFS(Tabla1[Avance_km],Tabla1[Ducto],Resumen!$B23,Tabla1[nombre_actividad],D$1)/$C23,0) -> 1 | E23: =IFERROR(SUMIFS(Tabla1[Avance_km],Tabla1[Ducto],Resumen!$B23,Tabla1[nombre_actividad],E$1)/$C23,0) -> 1 | F23: =IFERROR(SUMIFS(Tabla1[Avance_km],Tabla1[Ducto],Resumen!$B23,Tabla1[nombre_actividad],F$1)/$C23,0) -> 1 | G23: =IFERROR(SUMIFS(Tabla1[Avance_Med],Tabla1[Ducto],Resumen!$B23,Tabla1[nombre_actividad],G$1)/(1),0) -> 0 | J23: =+_xlfn.XLOOKUP(B23,'R (s01)'!B:B,'R (s01)'!J:J) -> 0
A24: =+_xlfn.XLOOKUP(B24,Tabla1[Ducto],Tabla1[Sistema],"") -> LIRA_GALERAS | B24: GPO. PRODUCTIVO LA LIRA | C24: =+_xlfn.XLOOKUP(B24,Tabla1[Ducto],Tabla1[Length]) -> 0.07 | D24: =IFERROR(SUMIFS(Tabla1[Avance_km],Tabla1[Ducto],Resumen!$B24,Tabla1[nombre_actividad],D$1)/$C24,0) -> 1 | E24: =IFERROR(SUMIFS(Tabla1[Avance_km],Tabla1[Ducto],Resumen!$B24,Tabla1[nombre_actividad],E$1)/$C24,0) -> 1 | F24: =IFERROR(SUMIFS(Tabla1[Avance_km],Tabla1[Ducto],Resumen!$B24,Tabla1[nombre_actividad],F$1)/$C24,0) -> 1 | G24: =IFERROR(SUMIFS(Tabla1[Avance_Med],Tabla1[Ducto],Resumen!$B24,Tabla1[nombre_actividad],G$1)/(1),0) -> 1 | J24: =+_xlfn.XLOOKUP(B24,'R (s01)'!B:B,'R (s01)'!J:J) -> 1
A25: =+_xlfn.XLOOKUP(B25,Tabla1[Ducto],Tabla1[Sistema],"") -> LIRA_GALERAS | B25: ED PARQUE INDUSTRIAL PYME | C25: =+_xlfn.XLOOKUP(B25,Tabla1[Ducto],Tabla1[Length]) -> 0.015 | D25: =IFERROR(SUMIFS(Tabla1[Avance_km],Tabla1[Ducto],Resumen!$B25,Tabla1[nombre_actividad],D$1)/$C25,0) -> 1 | E25: =IFERROR(SUMIFS(Tabla1[Avance_km],Tabla1[Ducto],Resumen!$B25,Tabla1[nombre_actividad],E$1)/$C25,0) -> 1 | F25: =IFERROR(SUMIFS(Tabla1[Avance_km],Tabla1[Ducto],Resumen!$B25,Tabla1[nombre_actividad],F$1)/$C25,0) -> 1 | G25: =IFERROR(SUMIFS(Tabla1[Avance_Med],Tabla1[Ducto],Resumen!$B25,Tabla1[nombre_actividad],G$1)/(1),0) -> 1 | J25: =+_xlfn.XLOOKUP(B25,'R (s01)'!B:B,'R (s01)'!J:J) -> 1
A26: =+_xlfn.XLOOKUP(B26,Tabla1[Ducto],Tabla1[Sistema],"") -> LIRA_GALERAS | B26: ED EL COLORADO | C26: =+_xlfn.XLOOKUP(B26,Tabla1[Ducto],Tabla1[Length]) -> 0.019 | D26: =IFERROR(SUMIFS(Tabla1[Avance_km],Tabla1[Ducto],Resumen!$B26,Tabla1[nombre_actividad],D$1)/$C26,0) -> 1 | E26: =IFERROR(SUMIFS(Tabla1[Avance_km],Tabla1[Ducto],Resumen!$B26,Tabla1[nombre_actividad],E$1)/$C26,0) -> 1 | F26: =IFERROR(SUMIFS(Tabla1[Avance_km],Tabla1[Ducto],Resumen!$B26,Tabla1[nombre_actividad],F$1)/$C26,0) -> 1 | G26: =IFERROR(SUMIFS(Tabla1[Avance_Med],Tabla1[Ducto],Resumen!$B26,Tabla1[nombre_actividad],G$1)/(ROUNDUP(C26,0)*2),0) -> 0.5 | J26: =+_xlfn.XLOOKUP(B26,'R (s01)'!B:B,'R (s01)'!J:J) -> 1
A27: =+_xlfn.XLOOKUP(B27,Tabla1[Ducto],Tabla1[Sistema],"") -> LIRA_GALERAS | B27: PILGRIMS LOS CUES | C27: =+_xlfn.XLOOKUP(B27,Tabla1[Ducto],Tabla1[Length]) -> 0.01 | D27: =IFERROR(SUMIFS(Tabla1[Avance_km],Tabla1[Ducto],Resumen!$B27,Tabla1[nombre_actividad],D$1)/$C27,0) -> 1 | E27: =IFERROR(SUMIFS(Tabla1[Avance_km],Tabla1[Ducto],Resumen!$B27,Tabla1[nombre_actividad],E$1)/$C27,0) -> 1 | F27: =IFERROR(SUMIFS(Tabla1[Avance_km],Tabla1[Ducto],Resumen!$B27,Tabla1[nombre_actividad],F$1)/$C27,0) -> 1 | G27: =IFERROR(SUMIFS(Tabla1[Avance_Med],Tabla1[Ducto],Resumen!$B27,Tabla1[nombre_actividad],G$1)/(1),0) -> 1 | J27: =+_xlfn.XLOOKUP(B27,'R (s01)'!B:B,'R (s01)'!J:J) -> 1
A28: =+_xlfn.XLOOKUP(B28,Tabla1[Ducto],Tabla1[Sistema],"") -> LIRA_GALERAS | B28: ED AEROTECH | C28: =+_xlfn.XLOOKUP(B28,Tabla1[Ducto],Tabla1[Length]) -> 0.267 | D28: =IFERROR(SUMIFS(Tabla1[Avance_km],Tabla1[Ducto],Resumen!$B28,Tabla1[nombre_actividad],D$1)/$C28,0) -> 1 | E28: =IFERROR(SUMIFS(Tabla1[Avance_km],Tabla1[Ducto],Resumen!$B28,Tabla1[nombre_actividad],E$1)/$C28,0) -> 1 | F28: =IFERROR(SUMIFS(Tabla1[Avance_km],Tabla1[Ducto],Resumen!$B28,Tabla1[nombre_actividad],F$1)/$C28,0) -> 1 | J28: =+_xlfn.XLOOKUP(B28,'R (s01)'!B:B,'R (s01)'!J:J) -> 2
A29: =+_xlfn.XLOOKUP(B29,Tabla1[Ducto],Tabla1[Sistema],"") -> LIRA_GALERAS | B29: FINSA II | C29: =+_xlfn.XLOOKUP(B29,Tabla1[Ducto],Tabla1[Length]) -> 0.01 | D29: =IFERROR(SUMIFS(Tabla1[Avance_km],Tabla1[Ducto],Resumen!$B29,Tabla1[nombre_actividad],D$1)/$C29,0) -> 1 | E29: =IFERROR(SUMIFS(Tabla1[Avance_km],Tabla1[Ducto],Resumen!$B29,Tabla1[nombre_actividad],E$1)/$C29,0) -> 1 | F29: =IFERROR(SUMIFS(Tabla1[Avance_km],Tabla1[Ducto],Resumen!$B29,Tabla1[nombre_actividad],F$1)/$C29,0) -> 1 | G29: =IFERROR(SUMIFS(Tabla1[Avance_Med],Tabla1[Ducto],Resumen!$B29,Tabla1[nombre_actividad],G$1)/(27),0) -> 0.037037037 | J29: =+_xlfn.XLOOKUP(B29,'R (s01)'!B:B,'R (s01)'!J:J) -> 1
A30: =+_xlfn.XLOOKUP(B30,Tabla1[Ducto],Tabla1[Sistema],"") -> LIRA_GALERAS | B30: STEERINGMEX | C30: =+_xlfn.XLOOKUP(B30,Tabla1[Ducto],Tabla1[Length]) -> 0.012 | D30: =IFERROR(SUMIFS(Tabla1[Avance_km],Tabla1[Ducto],Resumen!$B30,Tabla1[nombre_actividad],D$1)/$C30,0) -> 1 | E30: =IFERROR(SUMIFS(Tabla1[Avance_km],Tabla1[Ducto],Resumen!$B30,Tabla1[nombre_actividad],E$1)/$C30,0) -> 1 | F30: =IFERROR(SUMIFS(Tabla1[Avance_km],Tabla1[Ducto],Resumen!$B30,Tabla1[nombre_actividad],F$1)/$C30,0) -> 1 | G30: =IFERROR(SUMIFS(Tabla1[Avance_Med],Tabla1[Ducto],Resumen!$B30,Tabla1[nombre_actividad],G$1)/(2),0) -> 0 | J30: =+_xlfn.XLOOKUP(B30,'R (s01)'!B:B,'R (s01)'!J:J) -> 0
A31: =+_xlfn.XLOOKUP(B31,Tabla1[Ducto],Tabla1[Sistema],"") -> LIRA_GALERAS | B31: ATONGO | C31: =+_xlfn.XLOOKUP(B31,Tabla1[Ducto],Tabla1[Length]) -> 12.657 | D31: =IFERROR(SUMIFS(Tabla1[Avance_km],Tabla1[Ducto],Resumen!$B31,Tabla1[nombre_actividad],D$1)/$C31,0) -> 1 | E31: =IFERROR(SUMIFS(Tabla1[Avance_km],Tabla1[Ducto],Resumen!$B31,Tabla1[nombre_actividad],E$1)/$C31,0) -> 1 | F31: =IFERROR(SUMIFS(Tabla1[Avance_km],Tabla1[Ducto],Resumen!$B31,Tabla1[nombre_actividad],F$1)/$C31,0) -> 1 | G31: =IFERROR(SUMIFS(Tabla1[Avance_Med],Tabla1[Ducto],Resumen!$B31,Tabla1[nombre_actividad],G$1)/(1),0) -> 27 | J31: =+_xlfn.XLOOKUP(B31,'R (s01)'!B:B,'R (s01)'!J:J) -> 27
A32: =+_xlfn.XLOOKUP(B32,Tabla1[Ducto],Tabla1[Sistema],"") -> LIRA_GALERAS | B32: NATGAS EL MARQUES | C32: =+_xlfn.XLOOKUP(B32,Tabla1[Ducto],Tabla1[Length]) -> 1.054 | D32: =IFERROR(SUMIFS(Tabla1[Avance_km],Tabla1[Ducto],Resumen!$B32,Tabla1[nombre_actividad],D$1)/$C32,0) -> 1 | E32: =IFERROR(SUMIFS(Tabla1[Avance_km],Tabla1[Ducto],Resumen!$B32,Tabla1[nombre_actividad],E$1)/$C32,0) -> 1 | F32: =IFERROR(SUMIFS(Tabla1[Avance_km],Tabla1[Ducto],Resumen!$B32,Tabla1[nombre_actividad],F$1)/$C32,0) -> 1 | J32: =+_xlfn.XLOOKUP(B32,'R (s01)'!B:B,'R (s01)'!J:J) -> 2
A33: =+_xlfn.XLOOKUP(B33,Tabla1[Ducto],Tabla1[Sistema],"") -> LIRA_GALERAS | B33: IACNA DE MEXICO | C33: =+_xlfn.XLOOKUP(B33,Tabla1[Ducto],Tabla1[Length]) -> 0.01 | D33: =IFERROR(SUMIFS(Tabla1[Avance_km],Tabla1[Ducto],Resumen!$B33,Tabla1[nombre_actividad],D$1)/$C33,0) -> 1 | E33: =IFERROR(SUMIFS(Tabla1[Avance_km],Tabla1[Ducto],Resumen!$B33,Tabla1[nombre_actividad],E$1)/$C33,0) -> 1 | F33: =IFERROR(SUMIFS(Tabla1[Avance_km],Tabla1[Ducto],Resumen!$B33,Tabla1[nombre_actividad],F$1)/$C33,0) -> 1 | J33: =+_xlfn.XLOOKUP(B33,'R (s01)'!B:B,'R (s01)'!J:J) -> 1
A34: =+_xlfn.XLOOKUP(B34,Tabla1[Ducto],Tabla1[Sistema],"") -> LIRA_GALERAS | B34: KOPPERT | C34: =+_xlfn.XLOOKUP(B34,Tabla1[Ducto],Tabla1[Length]) -> 0.015 | D34: =IFERROR(SUMIFS(Tabla1[Avance_km],Tabla1[Ducto],Resumen!$B34,Tabla1[nombre_actividad],D$1)/$C34,0) -> 1 | E34: =IFERROR(SUMIFS(Tabla1[Avance_km],Tabla1[Ducto],Resumen!$B34,Tabla1[nombre_actividad],E$1)/$C34,0) -> 1 | F34: =IFERROR(SUMIFS(Tabla1[Avance_km],Tabla1[Ducto],Resumen!$B34,Tabla1[nombre_actividad],F$1)/$C34,0) -> 1 | J34: =+_xlfn.XLOOKUP(B34,'R (s01)'!B:B,'R (s01)'!J:J) -> 0
A35: =+_xlfn.XLOOKUP(B35,Tabla1[Ducto],Tabla1[Sistema],"") -> PECO_AGROS | B35: POLLOS QUERÉTARO | C35: =+_xlfn.XLOOKUP(B35,Tabla1[Ducto],Tabla1[Length]) -> 0.013 | D35: =IFERROR(SUMIFS(Tabla1[Avance_km],Tabla1[Ducto],Resumen!$B35,Tabla1[nombre_actividad],D$1)/$C35,0) -> 1 | E35: =IFERROR(SUMIFS(Tabla1[Avance_km],Tabla1[Ducto],Resumen!$B35,Tabla1[nombre_actividad],E$1)/$C35,0) -> 1 | F35: =IFERROR(SUMIFS(Tabla1[Avance_km],Tabla1[Ducto],Resumen!$B35,Tabla1[nombre_actividad],F$1)/$C35,0) -> 1 | J35: =+_xlfn.XLOOKUP(B35,'R (s01)'!B:B,'R (s01)'!J:J) -> #N/A
A36: =+_xlfn.XLOOKUP(B36,Tabla1[Ducto],Tabla1[Sistema],"") -> PECO_AGROS | B36: NUTEC LOS OLIVOS | C36: =+_xlfn.XLOOKUP(B36,Tabla1[Ducto],Tabla1[Length]) -> 0.011 | D36: =IFERROR(SUMIFS(Tabla1[Avance_km],Tabla1[Ducto],Resumen!$B36,Tabla1[nombre_actividad],D$1)/$C36,0) -> 1 | E36: =IFERROR(SUMIFS(Tabla1[Avance_km],Tabla1[Ducto],Resumen!$B36,Tabla1[nombre_actividad],E$1)/$C36,0) -> 1 | F36: =IFERROR(SUMIFS(Tabla1[Avance_km],Tabla1[Ducto],Resumen!$B36,Tabla1[nombre_actividad],F$1)/$C36,0) -> 1 | G36: =IFERROR(SUMIFS(Tabla1[Avance_Med],Tabla1[Ducto],Resumen!$B36,Tabla1[nombre_actividad],G$1)/(1),0) -> 0 | J36: =+_xlfn.XLOOKUP(B36,'R (s01)'!B:B,'R (s01)'!J:J) -> #N/A
A37: =+_xlfn.XLOOKUP(B37,Tabla1[Ducto],Tabla1[Sistema],"") -> PECO_AGROS | B37: ERM LA PERLA | C37: =+_xlfn.XLOOKUP(B37,Tabla1[Ducto],Tabla1[Length]) -> 0.006 | D37: =IFERROR(SUMIFS(Tabla1[Avance_km],Tabla1[Ducto],Resumen!$B37,Tabla1[nombre_actividad],D$1)/$C37,0) -> 1 | E37: =IFERROR(SUMIFS(Tabla1[Avance_km],Tabla1[Ducto],Resumen!$B37,Tabla1[nombre_actividad],E$1)/$C37,0) -> 1 | F37: =IFERROR(SUMIFS(Tabla1[Avance_km],Tabla1[Ducto],Resumen!$B37,Tabla1[nombre_actividad],F$1)/$C37,0) -> 1 | J37: =+_xlfn.XLOOKUP(B37,'R (s01)'!B:B,'R (s01)'!J:J) -> #N/A
A38: =+_xlfn.XLOOKUP(B38,Tabla1[Ducto],Tabla1[Sistema],"") -> LIRA_GALERAS | B38: ED PARQUE INDUSTRIAL LA BOMBA | C38: =+_xlfn.XLOOKUP(B38,Tabla1[Ducto],Tabla1[Length]) -> 0.088 | D38: =IFERROR(SUMIFS(Tabla1[Avance_km],Tabla1[Ducto],Resumen!$B38,Tabla1[nombre_actividad],D$1)/$C38,0) -> 1 | E38: =IFERROR(SUMIFS(Tabla1[Avance_km],Tabla1[Ducto],Resumen!$B38,Tabla1[nombre_actividad],E$1)/$C38,0) -> 1 | F38: =IFERROR(SUMIFS(Tabla1[Avance_km],Tabla1[Ducto],Resumen!$B38,Tabla1[nombre_actividad],F$1)/$C38,0) -> 1 | J38: =+_xlfn.XLOOKUP(B38,'R (s01)'!B:B,'R (s01)'!J:J) -> 1
A39: =+_xlfn.XLOOKUP(B39,Tabla1[Ducto],Tabla1[Sistema],"") -> LIRA_GALERAS | B39: STERLING BURDS | C39: =+_xlfn.XLOOKUP(B39,Tabla1[Ducto],Tabla1[Length]) -> 0.188 | D39: =IFERROR(SUMIFS(Tabla1[Avance_km],Tabla1[Ducto],Resumen!$B39,Tabla1[nombre_actividad],D$1)/$C39,0) -> 1 | E39: =IFERROR(SUMIFS(Tabla1[Avance_km],Tabla1[Ducto],Resumen!$B39,Tabla1[nombre_actividad],E$1)/$C39,0) -> 1 | F39: =IFERROR(SUMIFS(Tabla1[Avance_km],Tabla1[Ducto],Resumen!$B39,Tabla1[nombre_actividad],F$1)/$C39,0) -> 1 | J39: =+_xlfn.XLOOKUP(B39,'R (s01)'!B:B,'R (s01)'!J:J) -> 0
A40: =+_xlfn.XLOOKUP(B40,Tabla1[Ducto],Tabla1[Sistema],"") -> LIRA_GALERAS | B40: FABRICA DE JABON LA CORONA | C40: =+_xlfn.XLOOKUP(B40,Tabla1[Ducto],Tabla1[Length]) -> 0.007 | D40: =IFERROR(SUMIFS(Tabla1[Avance_km],Tabla1[Ducto],Resumen!$B40,Tabla1[nombre_actividad],D$1)/$C40,0) -> 1 | E40: =IFERROR(SUMIFS(Tabla1[Avance_km],Tabla1[Ducto],Resumen!$B40,Tabla1[nombre_actividad],E$1)/$C40,0) -> 1 | F40: =IFERROR(SUMIFS(Tabla1[Avance_km],Tabla1[Ducto],Resumen!$B40,Tabla1[nombre_actividad],F$1)/$C40,0) -> 1 | G40: =IFERROR(SUMIFS(Tabla1[Avance_Med],Tabla1[Ducto],Resumen!$B40,Tabla1[nombre_actividad],G$1)/(1),0) -> 0 | J40: =+_xlfn.XLOOKUP(B40,'R (s01)'!B:B,'R (s01)'!J:J) -> 0
...

Sheet Catálogo de conceptos
D1: Catálogo de conceptos: Regional DGQ / Evaluación directa por corrosión externa (ECDA) bajo el estándar practico SP0502-2010 (AMPP) en el total de red de distribucion de la regional DGQ en una longitud de 200 kilometros de red en direferentes diametros (10", 8", 6", 4", 3" y 2").
B3: Nombre del Proveedor | G3: PROYECTO:
G4: ECDA DGQ
B5: POSICIÓN | C5: DESCRIPCIÓN BREVE | G5: CANTIDAD | H5: UNIDAD DE MEDIDA (UM) | I5: PRECIO UNITARIO | J5: TOTAL | K5: MONEDA
B6: 1 | C6: ETAPA 1
B7: 1.1 | C7: Recopilación de Información | G7: 105 | H7: DUCTO | I7: 0 | J7: =I7*G7 -> 0 | K7: MXN
B8: 1.2 | C8: Análisis de Información | G8: 105 | H8: DUCTO | I8: 0 | J8: =I8*G8 -> 0 | K8: MXN
B9: 1.3 | C9: Evaluación de factibilidad de ECDA | G9: 105 | H9: DUCTO | I9: 0 | J9: =I9*G9 -> 0 | K9: MXN
B10: 1,4 | C10: Selección de técnicas de inspección indirecta | G10: 105 | H10: DUCTO | I10: 0 | J10: =I10*G10 -> 0 | K10: MXN
B11: 1.5 | C11: Definición de zonas ECDA | G11: 105 | H11: DUCTO | I11: 0 | J11: =I11*G11 -> 0 | K11: MXN
B12: 1.6 | C12: Reporte final entregable (con resultados, diagnosticos, hallazgos, recomendaciones y conclusiones). Esta partida puede reducir en funcion de la cantidad de ductos principales. | G12: 105 | H12: DUCTO | I12: 0 | J12: =I12*G12 -> 0 | K12: MXN
B13: 2 | C13: ETAPA 2 | I13: Subtotal | J13: =SUM(J7:J12) -> 0
B14: 2.1 | C14: Estudio de potencial a intervalos cortos (Close Interval Potential Survey-CIPS). | G14: 200 | H14: KM | I14: 0 | J14: =I14*G14 -> 0 | K14: MXN
B15: 2.2 | C15: Estudio Gradiente de Voltaje de Corriente Alterna (ACVG). | G15: 200 | H15: KM | I15: 0 | J15: =I15*G15 -> 0 | K15: MXN
B16: 2.3 | C16: Estudio Gradiente de Voltaje de Corriente Directa (DCVG). | G16: 200 | H16: KM | I16: 0 | J16: =I16*G16 -> 0 | K16: MXN
B17: 2.4 | C17: Mapeo de corriente PCM | G17: 200 | H17: KM | I17: 0 | J17: =I17*G17 -> 0 | K17: MXN
B18: 2.5 | C18: Levantamiento de resistividad pH y bacterias a lo largo de la trayectoria del ducto a cada 500 m Incluye mano de obra, kits y equipo | G18: 500 | H18: SERVICIOS | I18: 0 | J18: =I18*G18 -> 0 | K18: MXN
B19: 2.6 | C19: Localización de Ducto. | G19: 200 | H19: KM | I19: 0 | J19: =I19*G19 -> 0 | K19: MXN
